<?xml version="1.0" ?>
<!-- =================================================================================== -->
<!-- |    This document was autogenerated by xacro from valve.urdf.xacro               | -->
<!-- |    EDITING THIS FILE BY HAND IS NOT RECOMMENDED                                 | -->
<!-- =================================================================================== -->
<robot name="valve_model">
  <link name="valve_base"/>
  <link name="valve_gt">
    <parent link="valve_base"/>
    <inertial>
      <mass value="0.01"/>
      <origin rpy="0 0 0" xyz="0 0 0.0"/>
      <inertia ixx="0.000001" ixy="0.0" ixz="0.0" iyy="0.000001" iyz="0.0" izz="0.000001"/>
    </inertial>
  </link>
  <link name="wheel">
    <!-- <contact>
      <friction_anchor/>
      <stiffness value="30000.0"/>
      <damping value="1000.0"/>
      <spinning_friction value="0.1"/>
      <lateral_friction value="1.0"/>
    </contact> -->
    <inertial>
      <origin rpy="0 0 0" xyz="0 0 0"/>
      <mass value="1.0"/>
      <!-- Inertia of a torus radius = 0.12 and cross section radius 0.02-->
      <inertia ixx="0.00745" ixy="0.0" ixz="0.0" iyy="0.0147" iyz="0.0" izz="0.00745"/>
    </inertial>
    <collision>
      <origin rpy="3.14 0 0" xyz="0 0 0"/>
      <geometry>
        <mesh filename="package://piloting_demo/models/valve/meshes/valve.dae" scale="1.0 1.0 1.0"/>
      </geometry>
    </collision>
    <visual>
      <origin rpy="3.14 0 0" xyz="0 0 0"/>
      <geometry>
        <mesh filename="package://piloting_demo/models/valve/meshes/valve.stl" scale="1.0 1.0 1.0"/>
      </geometry>
    </visual>
  </link>
  <joint name="wheel_joint" type="continuous">
    <origin rpy="0.0 0 0" xyz="0 0 0"/>
    <axis rpy="0 0 0" xyz="0 0 1"/>
    <parent link="valve_gt"/>
    <child link="wheel"/>
    <dynamics damping="10.0" friction="10.0"/>
    <limit effort="30" lower="-3.14" upper="3.14" velocity="1.0"/>
  </joint>
  <!-- Gazebo simulation -->
  <transmission name="wheel_joint_transmission">
    <type>transmission_interface/SimpleTransmission</type>
    <joint name="wheel_joint">
      <hardwareInterface>hardware_interface/EffortJointInterface</hardwareInterface>
    </joint>
    <actuator name="wheel_joint_motor">
      <mechanicalReduction>1</mechanicalReduction>
    </actuator>
  </transmission>
  <gazebo>
    <plugin filename="libgazebo_ros_control.so" name="gazebo_ros_control">
      <legacyModeNS>true</legacyModeNS>
      <robotParam>valve_description</robotParam>
      <robotNamespace>valve</robotNamespace>
    </plugin>
  </gazebo>
</robot>

