<?xml version="1.0" encoding="utf-8"?>
<!-- =================================================================================== -->
<!-- |    This document was autogenerated by xacro from /home/marko/GS/catkin_ws/src/moma/moma_gazebo/data/models/cupboard_drawers/cupboard_drawers.urdf.xacro | -->
<!-- |    EDITING THIS FILE BY HAND IS NOT RECOMMENDED                                 | -->
<!-- =================================================================================== -->
<robot name="cupboard_drawers">
  <material name="white">
    <color rgba="1 1 1 1"/>
  </material>
  <material name="dark_brown">
    <color rgba="0.4 0.2 0.0 1"/>
  </material>
  <material name="light_brown">
    <color rgba="0.6 0.29 0.0 1"/>
  </material>
  <material name="silver">
    <color rgba="0.87 0.87 0.87 0.8"/>
  </material>
  <link name="base_link">
    <inertial>
      <origin rpy="0 0 0" xyz="0 0 0"/>
      <mass value="0.0"/>
      <inertia ixx="1" ixy="0" ixz="0" iyy="1" iyz="0" izz="1"/>
    </inertial>
  </link>
  <link name="frame_back_wall">
    <contact>
      <lateral_friction value="1.0"/>
    </contact>
    <inertial>
      <origin rpy="0 0 0" xyz="0 0 0"/>
      <mass value="0.2"/>
      <inertia ixx="1" ixy="0" ixz="0" iyy="1" iyz="0" izz="1"/>
    </inertial>
    <visual>
      <origin rpy="0 0 0" xyz="0 0 0"/>
      <geometry>
        <box size="0.84 0.03 0.64"/>
      </geometry>
      <material name="dark_brown"/>
    </visual>
    <collision>
      <origin rpy="0 0 0" xyz="0 0 0"/>
      <geometry>
        <box size="0.84 0.03 0.64"/>
      </geometry>
    </collision>
  </link>
  <link name="frame_bottom_wall">
    <contact>
      <lateral_friction value="1.0"/>
    </contact>
    <inertial>
      <origin rpy="0 0 0" xyz="0 0 0"/>
      <mass value="0.2"/>
      <inertia ixx="1" ixy="0" ixz="0" iyy="1" iyz="0" izz="1"/>
    </inertial>
    <visual>
      <origin rpy="0 0 0" xyz="0 0 0"/>
      <geometry>
        <box size="0.9 0.03 0.6"/>
      </geometry>
      <material name="dark_brown"/>
    </visual>
    <collision>
      <origin rpy="0 0 0" xyz="0 0 0"/>
      <geometry>
        <box size="0.9 0.03 0.6"/>
      </geometry>
    </collision>
  </link>
  <joint name="frame_bottom_joint" type="fixed">
    <origin rpy="1.57079632679 0 0" xyz="0 -0.285 -0.335"/>
    <parent link="frame_back_wall"/>
    <child link="frame_bottom_wall"/>
  </joint>
  <link name="frame_left_wall">
    <contact>
      <lateral_friction value="1.0"/>
    </contact>
    <inertial>
      <origin rpy="0 0 0" xyz="0 0 0"/>
      <mass value="0.2"/>
      <inertia ixx="1" ixy="0" ixz="0" iyy="1" iyz="0" izz="1"/>
    </inertial>
    <visual>
      <origin rpy="0 0 0" xyz="0 0 0"/>
      <geometry>
        <box size="0.6 0.03 0.64"/>
      </geometry>
      <material name="dark_brown"/>
    </visual>
    <collision>
      <origin rpy="0 0 0" xyz="0 0 0"/>
      <geometry>
        <box size="0.6 0.03 0.64"/>
      </geometry>
    </collision>
  </link>
  <joint name="frame_left_joint" type="fixed">
    <origin rpy="0 0 1.57079632679" xyz="-0.435 -0.285 0"/>
    <parent link="frame_back_wall"/>
    <child link="frame_left_wall"/>
  </joint>
  <link name="frame_right_wall">
    <contact>
      <lateral_friction value="1.0"/>
    </contact>
    <inertial>
      <origin rpy="0 0 0" xyz="0 0 0"/>
      <mass value="0.2"/>
      <inertia ixx="1" ixy="0" ixz="0" iyy="1" iyz="0" izz="1"/>
    </inertial>
    <visual>
      <origin rpy="0 0 0" xyz="0 0 0"/>
      <geometry>
        <box size="0.6 0.03 0.64"/>
      </geometry>
      <material name="dark_brown"/>
    </visual>
    <collision>
      <origin rpy="0 0 0" xyz="0 0 0"/>
      <geometry>
        <box size="0.6 0.03 0.64"/>
      </geometry>
    </collision>
  </link>
  <joint name="frame_right_joint" type="fixed">
    <origin rpy="0 0 1.57079632679" xyz="0.435 -0.285 0"/>
    <parent link="frame_back_wall"/>
    <child link="frame_right_wall"/>
  </joint>
  <link name="frame_top_wall">
    <contact>
      <lateral_friction value="1.0"/>
    </contact>
    <inertial>
      <origin rpy="0 0 0" xyz="0 0 0"/>
      <mass value="0.2"/>
      <inertia ixx="1" ixy="0" ixz="0" iyy="1" iyz="0" izz="1"/>
    </inertial>
    <visual>
      <origin rpy="0 0 0" xyz="0 0 0"/>
      <geometry>
        <box size="0.9 0.03 0.6"/>
      </geometry>
      <material name="dark_brown"/>
    </visual>
    <collision>
      <origin rpy="0 0 0" xyz="0 0 0"/>
      <geometry>
        <box size="0.9 0.03 0.6"/>
      </geometry>
    </collision>
  </link>
  <joint name="frame_top_joint" type="fixed">
    <origin rpy="1.57079632679 0 0" xyz="0 -0.285 0.335"/>
    <parent link="frame_back_wall"/>
    <child link="frame_top_wall"/>
  </joint>
  <joint name="frame_joint" type="fixed">
    <origin rpy="0 0 0" xyz="0 0.285 0.35"/>
    <parent link="base_link"/>
    <child link="frame_back_wall"/>
  </joint>
  <link name="drawer1_back_wall">
    <contact>
      <lateral_friction value="1.0"/>
    </contact>
    <inertial>
      <origin rpy="0 0 0" xyz="0 0 0"/>
      <mass value="0.2"/>
      <inertia ixx="1" ixy="0" ixz="0" iyy="1" iyz="0" izz="1"/>
    </inertial>
    <visual>
      <origin rpy="0 0 0" xyz="0 0 0"/>
      <geometry>
        <box size="0.8 0.015 0.535"/>
      </geometry>
      <material name="light_brown"/>
    </visual>
    <collision>
      <origin rpy="0 0 0" xyz="0 0 0"/>
      <geometry>
        <box size="0.8 0.015 0.535"/>
      </geometry>
    </collision>
  </link>
  <link name="drawer1_bottom_wall">
    <contact>
      <lateral_friction value="1.0"/>
    </contact>
    <inertial>
      <origin rpy="0 0 0" xyz="0 0 0"/>
      <mass value="0.2"/>
      <inertia ixx="1" ixy="0" ixz="0" iyy="1" iyz="0" izz="1"/>
    </inertial>
    <visual>
      <origin rpy="0 0 0" xyz="0 0 0"/>
      <geometry>
        <box size="0.83 0.015 0.15375"/>
      </geometry>
      <material name="light_brown"/>
    </visual>
    <collision>
      <origin rpy="0 0 0" xyz="0 0 0"/>
      <geometry>
        <box size="0.83 0.015 0.15375"/>
      </geometry>
    </collision>
  </link>
  <joint name="drawer1_bottom_joint" type="fixed">
    <origin rpy="1.57079632679 0 0" xyz="0 -0.069375 -0.275"/>
    <parent link="drawer1_back_wall"/>
    <child link="drawer1_bottom_wall"/>
  </joint>
  <link name="drawer1_left_wall">
    <contact>
      <lateral_friction value="1.0"/>
    </contact>
    <inertial>
      <origin rpy="0 0 0" xyz="0 0 0"/>
      <mass value="0.2"/>
      <inertia ixx="1" ixy="0" ixz="0" iyy="1" iyz="0" izz="1"/>
    </inertial>
    <visual>
      <origin rpy="0 0 0" xyz="0 0 0"/>
      <geometry>
        <box size="0.15375 0.015 0.535"/>
      </geometry>
      <material name="light_brown"/>
    </visual>
    <collision>
      <origin rpy="0 0 0" xyz="0 0 0"/>
      <geometry>
        <box size="0.15375 0.015 0.535"/>
      </geometry>
    </collision>
  </link>
  <joint name="drawer1_left_joint" type="fixed">
    <origin rpy="0 0 1.57079632679" xyz="-0.4075 -0.069375 0"/>
    <parent link="drawer1_back_wall"/>
    <child link="drawer1_left_wall"/>
  </joint>
  <link name="drawer1_right_wall">
    <contact>
      <lateral_friction value="1.0"/>
    </contact>
    <inertial>
      <origin rpy="0 0 0" xyz="0 0 0"/>
      <mass value="0.2"/>
      <inertia ixx="1" ixy="0" ixz="0" iyy="1" iyz="0" izz="1"/>
    </inertial>
    <visual>
      <origin rpy="0 0 0" xyz="0 0 0"/>
      <geometry>
        <box size="0.15375 0.015 0.535"/>
      </geometry>
      <material name="light_brown"/>
    </visual>
    <collision>
      <origin rpy="0 0 0" xyz="0 0 0"/>
      <geometry>
        <box size="0.15375 0.015 0.535"/>
      </geometry>
    </collision>
  </link>
  <joint name="drawer1_right_joint" type="fixed">
    <origin rpy="0 0 1.57079632679" xyz="0.4075 -0.069375 0"/>
    <parent link="drawer1_back_wall"/>
    <child link="drawer1_right_wall"/>
  </joint>
  <link name="drawer1_top_wall">
    <contact>
      <lateral_friction value="1.0"/>
    </contact>
    <inertial>
      <origin rpy="0 0 0" xyz="0 0 0"/>
      <mass value="0.2"/>
      <inertia ixx="1" ixy="0" ixz="0" iyy="1" iyz="0" izz="1"/>
    </inertial>
    <visual>
      <origin rpy="0 0 0" xyz="0 0 0"/>
      <geometry>
        <box size="0.83 0.015 0.15375"/>
      </geometry>
      <material name="light_brown"/>
    </visual>
    <collision>
      <origin rpy="0 0 0" xyz="0 0 0"/>
      <geometry>
        <box size="0.83 0.015 0.15375"/>
      </geometry>
    </collision>
  </link>
  <joint name="drawer1_top_joint" type="fixed">
    <origin rpy="1.57079632679 0 0" xyz="0 -0.069375 0.275"/>
    <parent link="drawer1_back_wall"/>
    <child link="drawer1_top_wall"/>
  </joint>
  <joint name="drawer_joint1" type="prismatic">
    <origin rpy="-1.57079632679 0 0" xyz="0 -0.0175 0.0425"/>
    <parent link="base_link"/>
    <child link="drawer1_back_wall"/>
    <axis xyz="0 0 -1"/>
    <dynamics damping="8.0"/>
    <limit effort="10.0" lower="0.0" upper="0.48" velocity="1.5"/>
  </joint>
  <link name="drawer1_handle">
    <inertial>
      <origin rpy="0 0 0" xyz="0 0 0"/>
      <mass value="0.2"/>
      <inertia ixx="1" ixy="0" ixz="0" iyy="1" iyz="0" izz="1"/>
    </inertial>
    <collision>
      <origin rpy="0 0 0" xyz="0 0 0"/>
      <geometry>
        <!-- <cylinder radius="0.01" length="${total_width*0.4}"/> -->
        <box size="0.015 0.015 0.36"/>
      </geometry>
    </collision>
    <visual>
      <origin rpy="0 0 0" xyz="0 0 0"/>
      <geometry>
        <!-- <cylinder radius="0.01" length="${total_width*0.4}"/> -->
        <box size="0.015 0.015 0.36"/>
      </geometry>
      <material name="silver"/>
    </visual>
  </link>
  <joint name="drawer1_handle_joint" type="fixed">
    <origin rpy="0 1.57079632679 0" xyz="0 -0.076875 -0.32"/>
    <parent link="drawer1_back_wall"/>
    <child link="drawer1_handle"/>
  </joint>
  <link name="drawer_handle_dummy_link1">
    <!-- This dummy link is added s.t. the handle is the parent of some link and we can find the handle's index. -->
    <inertial>
      <origin rpy="0 0 0" xyz="0 0 0"/>
      <mass value="0.1"/>
      <inertia ixx="1" ixy="0" ixz="0" iyy="1" iyz="0" izz="1"/>
    </inertial>
  </link>
  <joint name="drawer_handle_dummy_joint1" type="fixed">
    <origin rpy="0 0 0" xyz="0 0 0"/>
    <parent link="drawer1_handle"/>
    <child link="drawer_handle_dummy_link1"/>
  </joint>
  <link name="drawer2_back_wall">
    <contact>
      <lateral_friction value="1.0"/>
    </contact>
    <inertial>
      <origin rpy="0 0 0" xyz="0 0 0"/>
      <mass value="0.2"/>
      <inertia ixx="1" ixy="0" ixz="0" iyy="1" iyz="0" izz="1"/>
    </inertial>
    <visual>
      <origin rpy="0 0 0" xyz="0 0 0"/>
      <geometry>
        <box size="0.8 0.015 0.535"/>
      </geometry>
      <material name="light_brown"/>
    </visual>
    <collision>
      <origin rpy="0 0 0" xyz="0 0 0"/>
      <geometry>
        <box size="0.8 0.015 0.535"/>
      </geometry>
    </collision>
  </link>
  <link name="drawer2_bottom_wall">
    <contact>
      <lateral_friction value="1.0"/>
    </contact>
    <inertial>
      <origin rpy="0 0 0" xyz="0 0 0"/>
      <mass value="0.2"/>
      <inertia ixx="1" ixy="0" ixz="0" iyy="1" iyz="0" izz="1"/>
    </inertial>
    <visual>
      <origin rpy="0 0 0" xyz="0 0 0"/>
      <geometry>
        <box size="0.83 0.015 0.15375"/>
      </geometry>
      <material name="light_brown"/>
    </visual>
    <collision>
      <origin rpy="0 0 0" xyz="0 0 0"/>
      <geometry>
        <box size="0.83 0.015 0.15375"/>
      </geometry>
    </collision>
  </link>
  <joint name="drawer2_bottom_joint" type="fixed">
    <origin rpy="1.57079632679 0 0" xyz="0 -0.069375 -0.275"/>
    <parent link="drawer2_back_wall"/>
    <child link="drawer2_bottom_wall"/>
  </joint>
  <link name="drawer2_left_wall">
    <contact>
      <lateral_friction value="1.0"/>
    </contact>
    <inertial>
      <origin rpy="0 0 0" xyz="0 0 0"/>
      <mass value="0.2"/>
      <inertia ixx="1" ixy="0" ixz="0" iyy="1" iyz="0" izz="1"/>
    </inertial>
    <visual>
      <origin rpy="0 0 0" xyz="0 0 0"/>
      <geometry>
        <box size="0.15375 0.015 0.535"/>
      </geometry>
      <material name="light_brown"/>
    </visual>
    <collision>
      <origin rpy="0 0 0" xyz="0 0 0"/>
      <geometry>
        <box size="0.15375 0.015 0.535"/>
      </geometry>
    </collision>
  </link>
  <joint name="drawer2_left_joint" type="fixed">
    <origin rpy="0 0 1.57079632679" xyz="-0.4075 -0.069375 0"/>
    <parent link="drawer2_back_wall"/>
    <child link="drawer2_left_wall"/>
  </joint>
  <link name="drawer2_right_wall">
    <contact>
      <lateral_friction value="1.0"/>
    </contact>
    <inertial>
      <origin rpy="0 0 0" xyz="0 0 0"/>
      <mass value="0.2"/>
      <inertia ixx="1" ixy="0" ixz="0" iyy="1" iyz="0" izz="1"/>
    </inertial>
    <visual>
      <origin rpy="0 0 0" xyz="0 0 0"/>
      <geometry>
        <box size="0.15375 0.015 0.535"/>
      </geometry>
      <material name="light_brown"/>
    </visual>
    <collision>
      <origin rpy="0 0 0" xyz="0 0 0"/>
      <geometry>
        <box size="0.15375 0.015 0.535"/>
      </geometry>
    </collision>
  </link>
  <joint name="drawer2_right_joint" type="fixed">
    <origin rpy="0 0 1.57079632679" xyz="0.4075 -0.069375 0"/>
    <parent link="drawer2_back_wall"/>
    <child link="drawer2_right_wall"/>
  </joint>
  <link name="drawer2_top_wall">
    <contact>
      <lateral_friction value="1.0"/>
    </contact>
    <inertial>
      <origin rpy="0 0 0" xyz="0 0 0"/>
      <mass value="0.2"/>
      <inertia ixx="1" ixy="0" ixz="0" iyy="1" iyz="0" izz="1"/>
    </inertial>
    <visual>
      <origin rpy="0 0 0" xyz="0 0 0"/>
      <geometry>
        <box size="0.83 0.015 0.15375"/>
      </geometry>
      <material name="light_brown"/>
    </visual>
    <collision>
      <origin rpy="0 0 0" xyz="0 0 0"/>
      <geometry>
        <box size="0.83 0.015 0.15375"/>
      </geometry>
    </collision>
  </link>
  <joint name="drawer2_top_joint" type="fixed">
    <origin rpy="1.57079632679 0 0" xyz="0 -0.069375 0.275"/>
    <parent link="drawer2_back_wall"/>
    <child link="drawer2_top_wall"/>
  </joint>
  <joint name="drawer_joint2" type="prismatic">
    <origin rpy="-1.57079632679 0 0" xyz="0 -0.0175 0.20125"/>
    <parent link="base_link"/>
    <child link="drawer2_back_wall"/>
    <axis xyz="0 0 -1"/>
    <dynamics damping="8.0"/>
    <limit effort="10.0" lower="0.0" upper="0.48" velocity="1.5"/>
  </joint>
  <link name="drawer2_handle">
    <inertial>
      <origin rpy="0 0 0" xyz="0 0 0"/>
      <mass value="0.2"/>
      <inertia ixx="1" ixy="0" ixz="0" iyy="1" iyz="0" izz="1"/>
    </inertial>
    <collision>
      <origin rpy="0 0 0" xyz="0 0 0"/>
      <geometry>
        <!-- <cylinder radius="0.01" length="${total_width*0.4}"/> -->
        <box size="0.015 0.015 0.36"/>
      </geometry>
    </collision>
    <visual>
      <origin rpy="0 0 0" xyz="0 0 0"/>
      <geometry>
        <!-- <cylinder radius="0.01" length="${total_width*0.4}"/> -->
        <box size="0.015 0.015 0.36"/>
      </geometry>
      <material name="silver"/>
    </visual>
  </link>
  <joint name="drawer2_handle_joint" type="fixed">
    <origin rpy="0 1.57079632679 0" xyz="0 -0.076875 -0.32"/>
    <parent link="drawer2_back_wall"/>
    <child link="drawer2_handle"/>
  </joint>
  <link name="drawer_handle_dummy_link2">
    <!-- This dummy link is added s.t. the handle is the parent of some link and we can find the handle's index. -->
    <inertial>
      <origin rpy="0 0 0" xyz="0 0 0"/>
      <mass value="0.1"/>
      <inertia ixx="1" ixy="0" ixz="0" iyy="1" iyz="0" izz="1"/>
    </inertial>
  </link>
  <joint name="drawer_handle_dummy_joint2" type="fixed">
    <origin rpy="0 0 0" xyz="0 0 0"/>
    <parent link="drawer2_handle"/>
    <child link="drawer_handle_dummy_link2"/>
  </joint>
  <link name="drawer3_back_wall">
    <contact>
      <lateral_friction value="1.0"/>
    </contact>
    <inertial>
      <origin rpy="0 0 0" xyz="0 0 0"/>
      <mass value="0.2"/>
      <inertia ixx="1" ixy="0" ixz="0" iyy="1" iyz="0" izz="1"/>
    </inertial>
    <visual>
      <origin rpy="0 0 0" xyz="0 0 0"/>
      <geometry>
        <box size="0.8 0.015 0.535"/>
      </geometry>
      <material name="light_brown"/>
    </visual>
    <collision>
      <origin rpy="0 0 0" xyz="0 0 0"/>
      <geometry>
        <box size="0.8 0.015 0.535"/>
      </geometry>
    </collision>
  </link>
  <link name="drawer3_bottom_wall">
    <contact>
      <lateral_friction value="1.0"/>
    </contact>
    <inertial>
      <origin rpy="0 0 0" xyz="0 0 0"/>
      <mass value="0.2"/>
      <inertia ixx="1" ixy="0" ixz="0" iyy="1" iyz="0" izz="1"/>
    </inertial>
    <visual>
      <origin rpy="0 0 0" xyz="0 0 0"/>
      <geometry>
        <box size="0.83 0.015 0.15375"/>
      </geometry>
      <material name="light_brown"/>
    </visual>
    <collision>
      <origin rpy="0 0 0" xyz="0 0 0"/>
      <geometry>
        <box size="0.83 0.015 0.15375"/>
      </geometry>
    </collision>
  </link>
  <joint name="drawer3_bottom_joint" type="fixed">
    <origin rpy="1.57079632679 0 0" xyz="0 -0.069375 -0.275"/>
    <parent link="drawer3_back_wall"/>
    <child link="drawer3_bottom_wall"/>
  </joint>
  <link name="drawer3_left_wall">
    <contact>
      <lateral_friction value="1.0"/>
    </contact>
    <inertial>
      <origin rpy="0 0 0" xyz="0 0 0"/>
      <mass value="0.2"/>
      <inertia ixx="1" ixy="0" ixz="0" iyy="1" iyz="0" izz="1"/>
    </inertial>
    <visual>
      <origin rpy="0 0 0" xyz="0 0 0"/>
      <geometry>
        <box size="0.15375 0.015 0.535"/>
      </geometry>
      <material name="light_brown"/>
    </visual>
    <collision>
      <origin rpy="0 0 0" xyz="0 0 0"/>
      <geometry>
        <box size="0.15375 0.015 0.535"/>
      </geometry>
    </collision>
  </link>
  <joint name="drawer3_left_joint" type="fixed">
    <origin rpy="0 0 1.57079632679" xyz="-0.4075 -0.069375 0"/>
    <parent link="drawer3_back_wall"/>
    <child link="drawer3_left_wall"/>
  </joint>
  <link name="drawer3_right_wall">
    <contact>
      <lateral_friction value="1.0"/>
    </contact>
    <inertial>
      <origin rpy="0 0 0" xyz="0 0 0"/>
      <mass value="0.2"/>
      <inertia ixx="1" ixy="0" ixz="0" iyy="1" iyz="0" izz="1"/>
    </inertial>
    <visual>
      <origin rpy="0 0 0" xyz="0 0 0"/>
      <geometry>
        <box size="0.15375 0.015 0.535"/>
      </geometry>
      <material name="light_brown"/>
    </visual>
    <collision>
      <origin rpy="0 0 0" xyz="0 0 0"/>
      <geometry>
        <box size="0.15375 0.015 0.535"/>
      </geometry>
    </collision>
  </link>
  <joint name="drawer3_right_joint" type="fixed">
    <origin rpy="0 0 1.57079632679" xyz="0.4075 -0.069375 0"/>
    <parent link="drawer3_back_wall"/>
    <child link="drawer3_right_wall"/>
  </joint>
  <link name="drawer3_top_wall">
    <contact>
      <lateral_friction value="1.0"/>
    </contact>
    <inertial>
      <origin rpy="0 0 0" xyz="0 0 0"/>
      <mass value="0.2"/>
      <inertia ixx="1" ixy="0" ixz="0" iyy="1" iyz="0" izz="1"/>
    </inertial>
    <visual>
      <origin rpy="0 0 0" xyz="0 0 0"/>
      <geometry>
        <box size="0.83 0.015 0.15375"/>
      </geometry>
      <material name="light_brown"/>
    </visual>
    <collision>
      <origin rpy="0 0 0" xyz="0 0 0"/>
      <geometry>
        <box size="0.83 0.015 0.15375"/>
      </geometry>
    </collision>
  </link>
  <joint name="drawer3_top_joint" type="fixed">
    <origin rpy="1.57079632679 0 0" xyz="0 -0.069375 0.275"/>
    <parent link="drawer3_back_wall"/>
    <child link="drawer3_top_wall"/>
  </joint>
  <joint name="drawer_joint3" type="prismatic">
    <origin rpy="-1.57079632679 0 0" xyz="0 -0.0175 0.36"/>
    <parent link="base_link"/>
    <child link="drawer3_back_wall"/>
    <axis xyz="0 0 -1"/>
    <dynamics damping="8.0"/>
    <limit effort="10.0" lower="0.0" upper="0.48" velocity="1.5"/>
  </joint>
  <link name="drawer3_handle">
    <inertial>
      <origin rpy="0 0 0" xyz="0 0 0"/>
      <mass value="0.2"/>
      <inertia ixx="1" ixy="0" ixz="0" iyy="1" iyz="0" izz="1"/>
    </inertial>
    <collision>
      <origin rpy="0 0 0" xyz="0 0 0"/>
      <geometry>
        <!-- <cylinder radius="0.01" length="${total_width*0.4}"/> -->
        <box size="0.015 0.015 0.36"/>
      </geometry>
    </collision>
    <visual>
      <origin rpy="0 0 0" xyz="0 0 0"/>
      <geometry>
        <!-- <cylinder radius="0.01" length="${total_width*0.4}"/> -->
        <box size="0.015 0.015 0.36"/>
      </geometry>
      <material name="silver"/>
    </visual>
  </link>
  <joint name="drawer3_handle_joint" type="fixed">
    <origin rpy="0 1.57079632679 0" xyz="0 -0.076875 -0.32"/>
    <parent link="drawer3_back_wall"/>
    <child link="drawer3_handle"/>
  </joint>
  <link name="drawer_handle_dummy_link3">
    <!-- This dummy link is added s.t. the handle is the parent of some link and we can find the handle's index. -->
    <inertial>
      <origin rpy="0 0 0" xyz="0 0 0"/>
      <mass value="0.1"/>
      <inertia ixx="1" ixy="0" ixz="0" iyy="1" iyz="0" izz="1"/>
    </inertial>
  </link>
  <joint name="drawer_handle_dummy_joint3" type="fixed">
    <origin rpy="0 0 0" xyz="0 0 0"/>
    <parent link="drawer3_handle"/>
    <child link="drawer_handle_dummy_link3"/>
  </joint>
  <link name="drawer4_back_wall">
    <contact>
      <lateral_friction value="1.0"/>
    </contact>
    <inertial>
      <origin rpy="0 0 0" xyz="0 0 0"/>
      <mass value="0.2"/>
      <inertia ixx="1" ixy="0" ixz="0" iyy="1" iyz="0" izz="1"/>
    </inertial>
    <visual>
      <origin rpy="0 0 0" xyz="0 0 0"/>
      <geometry>
        <box size="0.8 0.015 0.535"/>
      </geometry>
      <material name="light_brown"/>
    </visual>
    <collision>
      <origin rpy="0 0 0" xyz="0 0 0"/>
      <geometry>
        <box size="0.8 0.015 0.535"/>
      </geometry>
    </collision>
  </link>
  <link name="drawer4_bottom_wall">
    <contact>
      <lateral_friction value="1.0"/>
    </contact>
    <inertial>
      <origin rpy="0 0 0" xyz="0 0 0"/>
      <mass value="0.2"/>
      <inertia ixx="1" ixy="0" ixz="0" iyy="1" iyz="0" izz="1"/>
    </inertial>
    <visual>
      <origin rpy="0 0 0" xyz="0 0 0"/>
      <geometry>
        <box size="0.83 0.015 0.15375"/>
      </geometry>
      <material name="light_brown"/>
    </visual>
    <collision>
      <origin rpy="0 0 0" xyz="0 0 0"/>
      <geometry>
        <box size="0.83 0.015 0.15375"/>
      </geometry>
    </collision>
  </link>
  <joint name="drawer4_bottom_joint" type="fixed">
    <origin rpy="1.57079632679 0 0" xyz="0 -0.069375 -0.275"/>
    <parent link="drawer4_back_wall"/>
    <child link="drawer4_bottom_wall"/>
  </joint>
  <link name="drawer4_left_wall">
    <contact>
      <lateral_friction value="1.0"/>
    </contact>
    <inertial>
      <origin rpy="0 0 0" xyz="0 0 0"/>
      <mass value="0.2"/>
      <inertia ixx="1" ixy="0" ixz="0" iyy="1" iyz="0" izz="1"/>
    </inertial>
    <visual>
      <origin rpy="0 0 0" xyz="0 0 0"/>
      <geometry>
        <box size="0.15375 0.015 0.535"/>
      </geometry>
      <material name="light_brown"/>
    </visual>
    <collision>
      <origin rpy="0 0 0" xyz="0 0 0"/>
      <geometry>
        <box size="0.15375 0.015 0.535"/>
      </geometry>
    </collision>
  </link>
  <joint name="drawer4_left_joint" type="fixed">
    <origin rpy="0 0 1.57079632679" xyz="-0.4075 -0.069375 0"/>
    <parent link="drawer4_back_wall"/>
    <child link="drawer4_left_wall"/>
  </joint>
  <link name="drawer4_right_wall">
    <contact>
      <lateral_friction value="1.0"/>
    </contact>
    <inertial>
      <origin rpy="0 0 0" xyz="0 0 0"/>
      <mass value="0.2"/>
      <inertia ixx="1" ixy="0" ixz="0" iyy="1" iyz="0" izz="1"/>
    </inertial>
    <visual>
      <origin rpy="0 0 0" xyz="0 0 0"/>
      <geometry>
        <box size="0.15375 0.015 0.535"/>
      </geometry>
      <material name="light_brown"/>
    </visual>
    <collision>
      <origin rpy="0 0 0" xyz="0 0 0"/>
      <geometry>
        <box size="0.15375 0.015 0.535"/>
      </geometry>
    </collision>
  </link>
  <joint name="drawer4_right_joint" type="fixed">
    <origin rpy="0 0 1.57079632679" xyz="0.4075 -0.069375 0"/>
    <parent link="drawer4_back_wall"/>
    <child link="drawer4_right_wall"/>
  </joint>
  <link name="drawer4_top_wall">
    <contact>
      <lateral_friction value="1.0"/>
    </contact>
    <inertial>
      <origin rpy="0 0 0" xyz="0 0 0"/>
      <mass value="0.2"/>
      <inertia ixx="1" ixy="0" ixz="0" iyy="1" iyz="0" izz="1"/>
    </inertial>
    <visual>
      <origin rpy="0 0 0" xyz="0 0 0"/>
      <geometry>
        <box size="0.83 0.015 0.15375"/>
      </geometry>
      <material name="light_brown"/>
    </visual>
    <collision>
      <origin rpy="0 0 0" xyz="0 0 0"/>
      <geometry>
        <box size="0.83 0.015 0.15375"/>
      </geometry>
    </collision>
  </link>
  <joint name="drawer4_top_joint" type="fixed">
    <origin rpy="1.57079632679 0 0" xyz="0 -0.069375 0.275"/>
    <parent link="drawer4_back_wall"/>
    <child link="drawer4_top_wall"/>
  </joint>
  <joint name="drawer_joint4" type="prismatic">
    <origin rpy="-1.57079632679 0 0" xyz="0 -0.0175 0.51875"/>
    <parent link="base_link"/>
    <child link="drawer4_back_wall"/>
    <axis xyz="0 0 -1"/>
    <dynamics damping="8.0"/>
    <limit effort="10.0" lower="0.0" upper="0.48" velocity="1.5"/>
  </joint>
  <link name="drawer4_handle">
    <inertial>
      <origin rpy="0 0 0" xyz="0 0 0"/>
      <mass value="0.2"/>
      <inertia ixx="1" ixy="0" ixz="0" iyy="1" iyz="0" izz="1"/>
    </inertial>
    <collision>
      <origin rpy="0 0 0" xyz="0 0 0"/>
      <geometry>
        <!-- <cylinder radius="0.01" length="${total_width*0.4}"/> -->
        <box size="0.015 0.015 0.36"/>
      </geometry>
    </collision>
    <visual>
      <origin rpy="0 0 0" xyz="0 0 0"/>
      <geometry>
        <!-- <cylinder radius="0.01" length="${total_width*0.4}"/> -->
        <box size="0.015 0.015 0.36"/>
      </geometry>
      <material name="silver"/>
    </visual>
  </link>
  <joint name="drawer4_handle_joint" type="fixed">
    <origin rpy="0 1.57079632679 0" xyz="0 -0.076875 -0.32"/>
    <parent link="drawer4_back_wall"/>
    <child link="drawer4_handle"/>
  </joint>
  <link name="drawer_handle_dummy_link4">
    <!-- This dummy link is added s.t. the handle is the parent of some link and we can find the handle's index. -->
    <inertial>
      <origin rpy="0 0 0" xyz="0 0 0"/>
      <mass value="0.1"/>
      <inertia ixx="1" ixy="0" ixz="0" iyy="1" iyz="0" izz="1"/>
    </inertial>
  </link>
  <joint name="drawer_handle_dummy_joint4" type="fixed">
    <origin rpy="0 0 0" xyz="0 0 0"/>
    <parent link="drawer4_handle"/>
    <child link="drawer_handle_dummy_link4"/>
  </joint>
</robot>

