<?xml version="1.0" ?>
<!-- =================================================================================== -->
<!-- |    This document was autogenerated by xacro from /local/home/harrisl/workspaces/moma_ws/src/moma/moma_description/urdf/giraffe.urdf.xacro | -->
<!-- |    EDITING THIS FILE BY HAND IS NOT RECOMMENDED                                 | -->
<!-- =================================================================================== -->
<robot name="giraffe">
    <link name="base_link" />
    <link name="base_footprint" />
    <joint name="base_joint" type="fixed">
        <origin rpy="0 0 0" xyz="0 0 0.0" />
        <parent link="base_link" />
        <child link="body_link" />
    </joint>
    <joint name="footprint_joint" type="fixed">
        <origin rpy="0 0 3.14" xyz="0.0 0.0 0.0" />
        <child link="base_link" />
        <parent link="base_footprint" />
    </joint>
    <link name="body_link">
        <inertial>
            <origin rpy="0 0 0" xyz="0 0 0" />
            <mass value="30.0" />
            <inertia ixx="1.52" ixy="0" ixz="0" iyy="1.28" iyz="0" izz="2.35225" />
        </inertial>
        <visual>
            <origin rpy="0 0 0" xyz="-0.17942 -0.295 0.2895" />
            <geometry>
                <mesh filename="package://gmp_robot/meshes/assembly_simplified.stl" scale="0.001 0.001 0.001" />
            </geometry>
            <material name="">
                <color rgba="0 0 1 1" />
            </material>
        </visual>
        <collision>
            <origin rpy="0 0 0" xyz="-0.17942 -0.295 0.2895" />
            <geometry>
                <mesh filename="package://gmp_robot/meshes/assembly_simplified.stl" scale="0.001 0.001 0.001" />
            </geometry>
        </collision>
    </link>
    <link name="steering_front_left_link">
        <inertial>
            <origin rpy="0 0 0" xyz="0 0 0" />
            <mass value="1.0" />
            <inertia ixx="0.001" ixy="0" ixz="0.0005" iyy="0" iyz="0" izz="0.001" />
        </inertial>
        <visual>
            <origin rpy="-1.5707963267949 1.5707963267949 0" xyz="0 0.02163 0" />
            <geometry>
                <mesh filename="package://gmp_robot/meshes/leg_simplified.stl" scale="0.001 0.001 0.001" />
            </geometry>
            <material name="">
                <color rgba="0.74902 0.74902 0.74902 1" />
            </material>
        </visual>
        <collision>
            <origin rpy="-1.5707963267949 1.5707963267949 0" xyz="0 0.02163 0" />
            <geometry>
                <mesh filename="package://gmp_robot/meshes/leg_simplified.stl" scale="0.001 0.001 0.001" />
                <!-- <box size="0.03 0.03 0.13"/> -->
            </geometry>
        </collision>
    </link>
    <joint name="steering_front_left" type="revolute">
        <origin rpy="1.5707963267949 0 0" xyz="-0.29 -0.255 0.2675" />
        <parent link="base_link" />
        <child link="steering_front_left_link" />
        <axis xyz="0 1 0" />
        <!-- <limit lower="-3.14" upper="3.14" effort="10" velocity="5" /> -->
        <limit effort="10" lower="-100" upper="100" velocity="5" />
    </joint>
    <link name="wheel_front_left_link">
        <inertial>
            <origin rpy="0 0 0" xyz="0 0 0" />
            <mass value="1.0" />
            <inertia ixx="0.005" ixy="0" ixz="0" iyy="0.0027" iyz="0" izz="0.0027" />
        </inertial>
        <visual>
            <!-- <origin        xyz="0 0 0"        rpy="0 0 0" /> -->
            <origin rpy="0 0 -1.5707963267949" xyz="0 0 0" />
            <geometry>
                <mesh filename="package://gmp_robot/meshes/wheel_simplified.stl" scale="0.001 0.001 0.001" />
                <!-- <cylinder length="0.06" radius="0.10"/> -->
            </geometry>
            <material name="">
                <color rgba="0.74902 0.74902 0.74902 1" />
            </material>
        </visual>
        <collision>
            <origin rpy="0 -1.5707963267949 0" xyz="0 0 0" />
            <geometry>
                <!-- <mesh          filename="package://gmp_robot/meshes/wheel_simplified.stl" scale="0.001 0.001 0.001"/> -->
                <cylinder length="0.06" radius="0.10" />
            </geometry>
            <max_contacts>1</max_contacts>
            <surface>
                <friction>
                    <ode>
                        <mu>1.0</mu>
                        <mu2>1.0</mu2>
                        <fdir1>0 0 1</fdir1>
                        <slip1>0.0</slip1>
                        <slip2>0.0</slip2>
                    </ode>
                </friction>
                <contact>
                    <ode>
                        <min_depth>0.005</min_depth>
                        <kp>1e8</kp>
                    </ode>
                </contact>
            </surface>
        </collision>
    </link>
    <joint name="wheel_front_left" type="continuous">
        <origin rpy="0 -1.5708 0" xyz="0 -0.1455 0" />
        <parent link="steering_front_left_link" />
        <child link="wheel_front_left_link" />
        <axis xyz="1 0 0" />
    </joint>
    <link name="steering_front_right_link">
        <inertial>
            <origin rpy="0 0 0" xyz="0 0 0" />
            <mass value="1.0" />
            <inertia ixx="0.001" ixy="0" ixz="0.0005" iyy="0" iyz="0" izz="0.001" />
        </inertial>
        <visual>
            <origin rpy="-1.5707963267949 1.5707963267949 0" xyz="0 0.02163 0" />
            <geometry>
                <mesh filename="package://gmp_robot/meshes/leg_simplified.stl" scale="0.001 0.001 0.001" />
            </geometry>
            <material name="">
                <color rgba="0.749019607843137 0.749019607843137 0.749019607843137 1" />
            </material>
        </visual>
        <collision>
            <origin rpy="-1.5707963267949 1.5707963267949 0" xyz="0 0.02163 0" />
            <geometry>
                <mesh filename="package://gmp_robot/meshes/leg_simplified.stl" scale="0.001 0.001 0.001" />
                <!-- <box size="0.03 0.03 0.13"/> -->
            </geometry>
        </collision>
    </link>
    <joint name="steering_front_right" type="revolute">
        <origin rpy="1.5707963267949 0 3.14" xyz="-0.29 0.255 0.2675" />
        <parent link="base_link" />
        <child link="steering_front_right_link" />
        <axis xyz="0 1 0" />
        <!-- <limit lower="-3.14" upper="3.14" effort="10" velocity="5" /> -->
        <limit effort="10" lower="-100" upper="100" velocity="5" />
    </joint>
    <link name="wheel_front_right_link">
        <inertial>
            <origin rpy="0 0 0" xyz="0 0 0" />
            <mass value="1.0" />
            <inertia ixx="0.005" ixy="0" ixz="0" iyy="0.0027" iyz="0" izz="0.0027" />
        </inertial>
        <visual>
            <origin rpy="0 0 -1.5707963267949" xyz="0 0 0" />
            <geometry>
                <mesh filename="package://gmp_robot/meshes/wheel_simplified.stl" scale="0.001 0.001 0.001" />
                <!-- <cylinder length="0.06" radius="0.10"/> -->
            </geometry>
            <material name="">
                <color rgba="0.74902 0.74902 0.74902 1" />
            </material>
        </visual>
        <collision>
            <origin rpy="0 -1.5707963267949 0" xyz="0 0 0" />
            <geometry>
                <!-- <mesh          filename="package://gmp_robot/meshes/wheel_simplified.stl" scale="0.001 0.001 0.001"/> -->
                <cylinder length="0.06" radius="0.10" />
            </geometry>
            <max_contacts>1</max_contacts>
            <surface>
                <friction>
                    <ode>
                        <mu>1.0</mu>
                        <mu2>1.0</mu2>
                        <fdir1>0 0 1</fdir1>
                        <slip1>0.0</slip1>
                        <slip2>0.0</slip2>
                    </ode>
                </friction>
                <contact>
                    <ode>
                        <min_depth>0.005</min_depth>
                        <kp>1e8</kp>
                    </ode>
                </contact>
            </surface>
        </collision>
    </link>
    <joint name="wheel_front_right" type="continuous">
        <origin rpy="0 -1.5708 0" xyz="0 -0.1455 0" />
        <parent link="steering_front_right_link" />
        <child link="wheel_front_right_link" />
        <axis xyz="-1 0 0" />
    </joint>
    <link name="steering_back_left_link">
        <inertial>
            <origin rpy="0 0 0" xyz="0 0 0" />
            <mass value="1.0" />
            <inertia ixx="0.001" ixy="0" ixz="0.0005" iyy="0" iyz="0" izz="0.001" />
        </inertial>
        <visual>
            <origin rpy="-1.5707963267949 1.5707963267949 0" xyz="0 0.02163 0" />
            <geometry>
                <mesh filename="package://gmp_robot/meshes/leg_simplified.stl" scale="0.001 0.001 0.001" />
            </geometry>
            <material name="">
                <color rgba="0.74902 0.74902 0.74902 1" />
            </material>
        </visual>
        <collision>
            <origin rpy="-1.5707963267949 1.5707963267949 0" xyz="0 0.02163 0" />
            <geometry>
                <mesh filename="package://gmp_robot/meshes/leg_simplified.stl" scale="0.001 0.001 0.001" />
                <!-- <box size="0.03 0.03 0.13"/> -->
            </geometry>
        </collision>
    </link>
    <joint name="steering_back_left" type="revolute">
        <origin rpy="1.5707963267949 0 0.0" xyz="0.29 -0.255 0.2675" />
        <parent link="base_link" />
        <child link="steering_back_left_link" />
        <axis xyz="0 1 0" />
        <!-- <limit lower="-3.14" upper="3.14" effort="10" velocity="5" /> -->
        <limit effort="10" lower="-100" upper="100" velocity="5" />
    </joint>
    <link name="wheel_back_left_link">
        <inertial>
            <origin rpy="0 0 0" xyz="0 0 0" />
            <mass value="1.0" />
            <inertia ixx="0.005" ixy="0" ixz="0" iyy="0.0027" iyz="0" izz="0.0027" />
        </inertial>
        <visual>
            <!-- <origin        xyz="0 0 0"        rpy="0 0 -1.5707963267949" /> -->
            <origin rpy="0 0 -1.5707963267949" xyz="0 0 0" />
            <geometry>
                <mesh filename="package://gmp_robot/meshes/wheel_simplified.stl" scale="0.001 0.001 0.001" />
            </geometry>
            <material name="">
                <color rgba="0.749019607843137 0.749019607843137 0.749019607843137 1" />
            </material>
        </visual>
        <collision>
            <origin rpy="0 -1.5707963267949 0" xyz="0 0 0" />
            <geometry>
                <!-- <mesh          filename="package://gmp_robot/meshes/wheel_simplified.stl" scale="0.001 0.001 0.001"/> -->
                <cylinder length="0.06" radius="0.10" />
            </geometry>
            <max_contacts>1</max_contacts>
            <surface>
                <friction>
                    <ode>
                        <mu>1.0</mu>
                        <mu2>1.0</mu2>
                        <fdir1>0 0 1</fdir1>
                        <slip1>0.0</slip1>
                        <slip2>0.0</slip2>
                    </ode>
                </friction>
                <contact>
                    <ode>
                        <min_depth>0.005</min_depth>
                        <kp>1e8</kp>
                    </ode>
                </contact>
            </surface>
        </collision>
    </link>
    <joint name="wheel_back_left" type="continuous">
        <origin rpy="0 -1.5708 0" xyz="0 -0.1455 0" />
        <parent link="steering_back_left_link" />
        <child link="wheel_back_left_link" />
        <axis xyz="1 0 0" />
    </joint>
    <link name="steering_back_right_link">
        <inertial>
            <origin rpy="0 0 0" xyz="0 0 0" />
            <mass value="1.0" />
            <inertia ixx="0.001" ixy="0" ixz="0.0005" iyy="0" iyz="0" izz="0.001" />
        </inertial>
        <visual>
            <origin rpy="-1.5707963267949 1.5707963267949 0" xyz="0 0.02163 0" />
            <geometry>
                <mesh filename="package://gmp_robot/meshes/leg_simplified.stl" scale="0.001 0.001 0.001" />
            </geometry>
            <material name="">
                <color rgba="0.74902 0.74902 0.74902 1" />
            </material>
        </visual>
        <collision>
            <origin rpy="-1.5707963267949 1.5707963267949 0" xyz="0 0.02163 0" />
            <geometry>
                <mesh filename="package://gmp_robot/meshes/leg_simplified.stl" scale="0.001 0.001 0.001" />
                <!-- <box size="0.03 0.03 0.13"/> -->
            </geometry>
        </collision>
    </link>
    <joint name="steering_back_right" type="revolute">
        <origin rpy="1.5707963267949 0 3.14" xyz="0.29 0.255 0.2675" />
        <parent link="base_link" />
        <child link="steering_back_right_link" />
        <axis xyz="0 1 0" />
        <!-- <limit lower="-3.14" upper="3.14" effort="10" velocity="5" /> -->
        <limit effort="10" lower="-100" upper="100" velocity="5" />
    </joint>
    <link name="wheel_back_right_link">
        <inertial>
            <origin rpy="0 0 0" xyz="0 0 0" />
            <mass value="1.0" />
            <inertia ixx="0.005" ixy="0" ixz="0" iyy="0.0027" iyz="0" izz="0.0027" />
        </inertial>
        <visual>
            <origin rpy="0 0 -1.5707963267949" xyz="0 0 0" />
            <geometry>
                <mesh filename="package://gmp_robot/meshes/wheel_simplified.stl" scale="0.001 0.001 0.001" />
                <!-- <cylinder length="0.06" radius="0.10"/> -->
            </geometry>
            <material name="">
                <color rgba="0.74902 0.74902 0.74902 1" />
            </material>
        </visual>
        <collision>
            <origin rpy="0 -1.5707963267949 0" xyz="0 0 0" />
            <geometry>
                <!-- <mesh          filename="package://gmp_robot/meshes/wheel_simplified.stl" scale="0.001 0.001 0.001"/> -->
                <cylinder length="0.06" radius="0.10" />
            </geometry>
            <max_contacts>1</max_contacts>
            <surface>
                <friction>
                    <ode>
                        <mu>1.0</mu>
                        <mu2>1.0</mu2>
                        <fdir1>0 0 1</fdir1>
                        <slip1>0.0</slip1>
                        <slip2>0.0</slip2>
                    </ode>
                </friction>
                <contact>
                    <ode>
                        <min_depth>0.005</min_depth>
                        <kp>1e8</kp>
                    </ode>
                </contact>
            </surface>
        </collision>
    </link>
    <joint name="wheel_back_right" type="continuous">
        <origin rpy="0 -1.5708 0" xyz="0 -0.1455 0" />
        <parent link="steering_back_right_link" />
        <child link="wheel_back_right_link" />
        <axis xyz="-1 0 0" />
    </joint>
    <link name="z_axis_link">
        <inertial>
            <origin rpy="0 0 0" xyz="0 0 0" />
            <mass value="3.0" />
            <inertia ixx="0.005" ixy="0" ixz="0" iyy="0.0027" iyz="0" izz="0.0027" />
        </inertial>
        <visual>
            <origin rpy="0 0 0" xyz="-0.17942 -0.295 0.0" />
            <geometry>
                <mesh filename="package://gmp_robot/meshes/z_axis_simplified.stl" scale="0.001 0.001 0.001" />
            </geometry>
            <material name="">
                <color rgba="0 0 1 1" />
            </material>
        </visual>
        <collision>
            <origin rpy="0 0 0" xyz="-0.17942 -0.295 0.0" />
            <geometry>
                <mesh filename="package://gmp_robot/meshes/z_axis_simplified.stl" scale="0.001 0.001 0.001" />
            </geometry>
        </collision>
    </link>
    <joint name="z_axis" type="prismatic">
        <origin rpy="0 0 0" xyz="0 0 0.3345" />
        <!-- <origin      xyz="0 0 0.5345"      rpy="0 0 0" /> -->
        <parent link="base_link" />
        <child link="z_axis_link" />
        <axis xyz="0 0 1" />
        <limit effort="100" lower="0" upper="0.305" velocity="5" />
        <!-- <limit lower="-0.2" upper="0.105" effort="1" velocity="5" /> -->
    </joint>
    <link name="front_laser_link">
        <visual>
            <geometry>
                <cylinder length="0.04" radius="0.05" />
            </geometry>
            <material name="">
                <color rgba="0.7803921568627451 0.6235294117647059 0.9372549019607843 1.0" />
            </material>
        </visual>
        <collision>
            <geometry>
                <cylinder length="0.04" radius="0.05" />
            </geometry>
        </collision>
        <inertial>
            <origin rpy="0 0 0" xyx="0 0 0" xyz="0 0 0" />
            <mass value="0.1" />
            <inertia ixx="0.0000758" ixy="0" ixz="0" iyy="0.0000758" iyz="0" izz="0.0000758" />
        </inertial>
    </link>
    <joint name="front_laser_joint" type="fixed">
        <parent link="body_link" />
        <child link="front_laser_link" />
        <origin rpy="0 0 0" xyz="-0.38 0 0.25" />
    </joint>
    <link name="back_laser_link">
        <visual>
            <geometry>
                <cylinder length="0.04" radius="0.05" />
            </geometry>
            <material name="">
                <color rgba="0.7803921568627451 0.6235294117647059 0.9372549019607843 1.0" />
            </material>
        </visual>
        <collision>
            <geometry>
                <cylinder length="0.04" radius="0.05" />
            </geometry>
        </collision>
        <inertial>
            <origin rpy="0 0 0" xyx="0 0 0" xyz="0 0 0" />
            <mass value="0.1" />
            <inertia ixx="0.0000758" ixy="0" ixz="0" iyy="0.0000758" iyz="0" izz="0.0000758" />
        </inertial>
    </link>
    <joint name="back_laser_joint" type="fixed">
        <parent link="body_link" />
        <child link="back_laser_link" />
        <origin rpy="0 0 0" xyz="0.38 0 0.25" />
    </joint>
    <gazebo reference="body_link">
        <material>Gazebo/Grey</material>
        <plugin name="gazebo_ros_control">
            <robotNamespace>/</robotNamespace>
        </plugin>
    </gazebo>
    <gazebo reference="steering_front_left_link">
        <material>Gazebo/Green</material>
        <mu1>1.0</mu1>
        <mu2>1.0</mu2>
        <kp>1000000.0</kp>
        <kd>100.0</kd>
    </gazebo>
    <gazebo reference="steering_front_right_link">
        <material>Gazebo/Green</material>
        <mu1>1.0</mu1>
        <mu2>1.0</mu2>
        <kp>1000000.0</kp>
        <kd>100.0</kd>
    </gazebo>
    <gazebo reference="steering_back_left_link">
        <material>Gazebo/Green</material>
        <mu1>1.0</mu1>
        <mu2>1.0</mu2>
        <kp>1000000.0</kp>
        <kd>100.0</kd>
    </gazebo>
    <gazebo reference="steering_back_right_link">
        <material>Gazebo/Green</material>
        <mu1>1.0</mu1>
        <mu2>1.0</mu2>
        <kp>1000000.0</kp>
        <kd>100.0</kd>
    </gazebo>
    <!-- Wheel friction set to zero  -->
    <gazebo reference="wheel_front_left_link">
        <material>Gazebo/Orange</material>
        <mu1>1.0</mu1>
        <mu2>1.0</mu2>
        <kp>1000000.0</kp>
        <kd>100.0</kd>
    </gazebo>
    <gazebo reference="wheel_front_right_link">
        <material>Gazebo/Orange</material>
        <mu1>1.0</mu1>
        <mu2>1.0</mu2>
        <kp>1000000.0</kp>
        <kd>100.0</kd>
    </gazebo>
    <gazebo reference="wheel_back_left_link">
        <material>Gazebo/Orange</material>
        <mu1>1.0</mu1>
        <mu2>1.0</mu2>
        <kp>1000000.0</kp>
        <kd>100.0</kd>
    </gazebo>
    <gazebo reference="wheel_back_right_link">
        <material>Gazebo/Orange</material>
        <mu1>1.0</mu1>
        <mu2>1.0</mu2>
        <kp>1000000.0</kp>
        <kd>100.0</kd>
    </gazebo>
    <gazebo reference="z_axis_link">
        <material>Gazebo/Blue</material>
        <!-- <mu1>20.0</mu1> -->
        <!-- <mu2>10.0</mu2> -->
        <!-- <kp>1000000.0</kp> -->
        <!-- <kd>100.0</kd> -->
    </gazebo>
    <gazebo reference="front_laser_link">
        <material>Gazebo/Purple</material>
        <sensor name="laser" type="ray">
            <pose>0 0 0 0 0 0</pose>
            <visualize>true</visualize>
            <update_rate>10</update_rate>
            <ray>
                <scan>
                    <horizontal>
                        <samples>1600</samples>
                        <min_angle>-3.14</min_angle>
                        <max_angle>3.14</max_angle>
                    </horizontal>
                </scan>
                <range>
                    <min>0.5</min>
                    <max>20</max>
                    <resolution>0.01</resolution>
                </range>
            </ray>
            <plugin filename="libgazebo_ros_laser.so" name="laser_controller">
                <frameName>front_laser_link</frameName>
                <hokuyoMinIntensity>101</hokuyoMinIntensity>
                <topicName>front/scan</topicName>
            </plugin>
        </sensor>
    </gazebo>
    <gazebo reference="back_laser_link">
        <material>Gazebo/Purple</material>
        <sensor name="laser" type="ray">
            <pose>0 0 0 0 0 0</pose>
            <visualize>true</visualize>
            <update_rate>10</update_rate>
            <ray>
                <scan>
                    <horizontal>
                        <samples>1600</samples>
                        <min_angle>-3.14</min_angle>
                        <max_angle>3.14</max_angle>
                    </horizontal>
                </scan>
                <range>
                    <min>0.5</min>
                    <max>20</max>
                    <resolution>0.01</resolution>
                </range>
            </ray>
            <plugin filename="libgazebo_ros_laser.so" name="laser_controller">
                <frameName>back_laser_link</frameName>
                <hokuyoMinIntensity>101</hokuyoMinIntensity>
                <topicName>back/scan</topicName>
            </plugin>
        </sensor>
    </gazebo>
    <gazebo>
        <plugin filename="libgazebo_ros_control.so" name="gazebo_ros_control">
            <robotNamespace>/</robotNamespace>
            <robotSimType>gazebo_ros_control/DefaultRobotHWSim</robotSimType>
            <broadcastTF>false</broadcastTF>
        </plugin>
    </gazebo>
    <transmission name="steering_front_left">
        <type>transmission_interface/SimpleTransmission</type>
        <joint name="steering_front_left">
            <hardwareInterface>hardware_interface/PositionJointInterface</hardwareInterface>
        </joint>
        <actuator name="steering_front_left">
            <mechanicalReduction>1</mechanicalReduction>
            <motorTorqueConstant>1</motorTorqueConstant>
            <hardwareInterface>hardware_interface/EffortJointInterface</hardwareInterface>
        </actuator>
    </transmission>
    <transmission name="steering_front_right">
        <type>transmission_interface/SimpleTransmission</type>
        <joint name="steering_front_right">
            <hardwareInterface>hardware_interface/PositionJointInterface</hardwareInterface>
        </joint>
        <actuator name="steering_front_right">
            <mechanicalReduction>1</mechanicalReduction>
            <motorTorqueConstant>1</motorTorqueConstant>
            <hardwareInterface>hardware_interface/EffortJointInterface</hardwareInterface>
        </actuator>
    </transmission>
    <transmission name="steering_back_left">
        <type>transmission_interface/SimpleTransmission</type>
        <joint name="steering_back_left">
            <hardwareInterface>hardware_interface/PositionJointInterface</hardwareInterface>
        </joint>
        <actuator name="steering_back_left">
            <mechanicalReduction>1</mechanicalReduction>
            <motorTorqueConstant>1</motorTorqueConstant>
            <hardwareInterface>hardware_interface/EffortJointInterface</hardwareInterface>
        </actuator>
    </transmission>
    <transmission name="steering_back_right">
        <type>transmission_interface/SimpleTransmission</type>
        <joint name="steering_back_right">
            <hardwareInterface>hardware_interface/PositionJointInterface</hardwareInterface>
        </joint>
        <actuator name="steering_back_right">
            <mechanicalReduction>1</mechanicalReduction>
            <motorTorqueConstant>1</motorTorqueConstant>
            <hardwareInterface>hardware_interface/EffortJointInterface</hardwareInterface>
        </actuator>
    </transmission>
    <transmission name="wheel_front_left">
        <type>transmission_interface/SimpleTransmission</type>
        <joint name="wheel_front_left">
            <hardwareInterface>hardware_interface/VelocityJointInterface</hardwareInterface>
        </joint>
        <actuator name="wheel_front_left">
            <mechanicalReduction>1</mechanicalReduction>
            <motorTorqueConstant>1</motorTorqueConstant>
            <hardwareInterface>hardware_interface/EffortJointInterface</hardwareInterface>
        </actuator>
    </transmission>
    <transmission name="wheel_front_right">
        <type>transmission_interface/SimpleTransmission</type>
        <joint name="wheel_front_right">
            <hardwareInterface>hardware_interface/VelocityJointInterface</hardwareInterface>
        </joint>
        <actuator name="wheel_front_right">
            <mechanicalReduction>1</mechanicalReduction>
            <motorTorqueConstant>1</motorTorqueConstant>
            <hardwareInterface>hardware_interface/EffortJointInterface</hardwareInterface>
        </actuator>
    </transmission>
    <transmission name="wheel_back_left">
        <type>transmission_interface/SimpleTransmission</type>
        <joint name="wheel_back_left">
            <hardwareInterface>hardware_interface/VelocityJointInterface</hardwareInterface>
        </joint>
        <actuator name="wheel_back_left">
            <mechanicalReduction>1</mechanicalReduction>
            <motorTorqueConstant>1</motorTorqueConstant>
            <hardwareInterface>hardware_interface/EffortJointInterface</hardwareInterface>
        </actuator>
    </transmission>
    <transmission name="wheel_back_right">
        <type>transmission_interface/SimpleTransmission</type>
        <joint name="wheel_back_right">
            <hardwareInterface>hardware_interface/VelocityJointInterface</hardwareInterface>
        </joint>
        <actuator name="wheel_back_right">
            <mechanicalReduction>1</mechanicalReduction>
            <motorTorqueConstant>1</motorTorqueConstant>
            <hardwareInterface>hardware_interface/EffortJointInterface</hardwareInterface>
        </actuator>
    </transmission>
    <transmission name="z_axis">
        <type>transmission_interface/SimpleTransmission</type>
        <joint name="z_axis">
            <hardwareInterface>hardware_interface/VelocityJointInterface</hardwareInterface>
        </joint>
        <actuator name="z_axis">
            <mechanicalReduction>1</mechanicalReduction>
            <!-- <motorTorqueConstant>1</motorTorqueConstant> -->
            <hardwareInterface>hardware_interface/EffortJointInterface</hardwareInterface>
        </actuator>
    </transmission>
    <gazebo>
        <plugin filename="libgazebo_ros_p3d.so" name="ground_truth">
            <alwaysOn>true</alwaysOn>
            <updateRate>50.0</updateRate>
            <gaussianNoise>0.01</gaussianNoise>
            <bodyName>base_footprint</bodyName>
            <topicName>odom</topicName>
        </plugin>
    </gazebo>
    <!-- add link in z-link -->
    <link name="franka_mount_link" />
    <joint name="arm_mount_joint" type="fixed">
        <parent link="z_axis_link" />
        <child link="franka_mount_link" />
        <origin rpy="0 0 3.141" xyz="-0.285 0.0 0.0325" />
    </joint>
    <index rpy="1 2 3" xyz="1 2 3" />
    <!-- sub-link defining detailed meshes for collision with environment -->
    <link name="panda_link0">
        <visual>
            <geometry>
                <mesh filename="package://franka_description/meshes/visual/link0.dae" />
            </geometry>
        </visual>
        <collision>
            <geometry>
                <mesh filename="package://franka_description/meshes/collision/link0.stl" />
            </geometry>
        </collision>
        <inertial>
            <origin rpy="0 0 0" xyz="-0.041018 -0.00014 0.049974" />
            <mass value="0.629769" />
            <inertia ixx="0.00315" ixy="8.2904e-07" ixz="0.00015" iyy="0.00388" iyz="8.2299e-06" izz="0.004285" />
        </inertial>
    </link>
    <!-- sub-link defining coarse geometries of real robot's internal self-collision -->
    <link name="panda_link0_sc" />
    <!-- fixed joint between both sub-links -->
    <joint name="panda_link0_sc_joint" type="fixed">
        <origin rpy="0 0 0" />
        <parent link="panda_link0" />
        <child link="panda_link0_sc" />
    </joint>
    <!-- sub-link defining detailed meshes for collision with environment -->
    <link name="panda_link1">
        <visual>
            <geometry>
                <mesh filename="package://franka_description/meshes/visual/link1.dae" />
            </geometry>
        </visual>
        <collision>
            <geometry>
                <mesh filename="package://franka_description/meshes/collision/link1.stl" />
            </geometry>
        </collision>
        <inertial>
            <origin rpy="0 0 0" xyz="0.003875 0.002081 -0.04762" />
            <mass value="4.970684" />
            <inertia ixx="0.70337" ixy="-0.000139" ixz="0.006772" iyy="0.70661" iyz="0.019169" izz="0.009117" />
        </inertial>
    </link>
    <!-- sub-link defining coarse geometries of real robot's internal self-collision -->
    <link name="panda_link1_sc" />
    <!-- fixed joint between both sub-links -->
    <joint name="panda_link1_sc_joint" type="fixed">
        <origin rpy="0 0 0" />
        <parent link="panda_link1" />
        <child link="panda_link1_sc" />
    </joint>
    <joint name="panda_joint1" type="revolute">
        <origin rpy="0 0 0" xyz="0 0 0.333" />
        <parent link="panda_link0" />
        <child link="panda_link1" />
        <axis xyz="0 0 1" />
        <limit effort="87.0" lower="-2.8973" upper="2.8973" velocity="2.175" />
        <safety_controller k_position="100.0" k_velocity="40.0" soft_lower_limit="-2.8973" soft_upper_limit="2.8973" />
        <dynamics D="1" K="7000" damping="0.003" friction="0.0" mu_coulomb="0" mu_viscous="16" />
    </joint>
    <!-- sub-link defining detailed meshes for collision with environment -->
    <link name="panda_link2">
        <visual>
            <geometry>
                <mesh filename="package://franka_description/meshes/visual/link2.dae" />
            </geometry>
        </visual>
        <collision>
            <geometry>
                <mesh filename="package://franka_description/meshes/collision/link2.stl" />
            </geometry>
        </collision>
        <inertial>
            <origin rpy="0 0 0" xyz="-0.003141 -0.02872  0.003495" />
            <mass value="0.646926" />
            <inertia ixx="0.007962" ixy="-0.003925" ixz="0.010254" iyy="0.02811" iyz="0.000704" izz="0.025995" />
        </inertial>
    </link>
    <!-- sub-link defining coarse geometries of real robot's internal self-collision -->
    <link name="panda_link2_sc" />
    <!-- fixed joint between both sub-links -->
    <joint name="panda_link2_sc_joint" type="fixed">
        <origin rpy="0 0 0" />
        <parent link="panda_link2" />
        <child link="panda_link2_sc" />
    </joint>
    <joint name="panda_joint2" type="revolute">
        <origin rpy="-1.5707963267948966 0 0" xyz="0 0 0" />
        <parent link="panda_link1" />
        <child link="panda_link2" />
        <axis xyz="0 0 1" />
        <limit effort="87.0" lower="-1.7628" upper="1.7628" velocity="2.175" />
        <safety_controller k_position="100.0" k_velocity="40.0" soft_lower_limit="-1.7628" soft_upper_limit="1.7628" />
        <dynamics D="1" K="7000" damping="0.003" friction="0.0" mu_coulomb="0" mu_viscous="16" />
    </joint>
    <!-- sub-link defining detailed meshes for collision with environment -->
    <link name="panda_link3">
        <visual>
            <geometry>
                <mesh filename="package://franka_description/meshes/visual/link3.dae" />
            </geometry>
        </visual>
        <collision>
            <geometry>
                <mesh filename="package://franka_description/meshes/collision/link3.stl" />
            </geometry>
        </collision>
        <inertial>
            <origin rpy="0 0 0" xyz="2.7518e-02 3.9252e-02 -6.6502e-02" />
            <mass value="3.228604" />
            <inertia ixx="0.037242" ixy="-0.004761" ixz="-0.011396" iyy="0.036155" iyz="-0.012805" izz="0.01083" />
        </inertial>
    </link>
    <!-- sub-link defining coarse geometries of real robot's internal self-collision -->
    <link name="panda_link3_sc" />
    <!-- fixed joint between both sub-links -->
    <joint name="panda_link3_sc_joint" type="fixed">
        <origin rpy="0 0 0" />
        <parent link="panda_link3" />
        <child link="panda_link3_sc" />
    </joint>
    <joint name="panda_joint3" type="revolute">
        <origin rpy="1.5707963267948966 0 0" xyz="0 -0.316 0" />
        <parent link="panda_link2" />
        <child link="panda_link3" />
        <axis xyz="0 0 1" />
        <limit effort="87.0" lower="-2.8973" upper="2.8973" velocity="2.175" />
        <safety_controller k_position="100.0" k_velocity="40.0" soft_lower_limit="-2.8973" soft_upper_limit="2.8973" />
        <dynamics D="1" K="7000" damping="0.003" friction="0.0" mu_coulomb="0" mu_viscous="16" />
    </joint>
    <!-- sub-link defining detailed meshes for collision with environment -->
    <link name="panda_link4">
        <visual>
            <geometry>
                <mesh filename="package://franka_description/meshes/visual/link4.dae" />
            </geometry>
        </visual>
        <collision>
            <geometry>
                <mesh filename="package://franka_description/meshes/collision/link4.stl" />
            </geometry>
        </collision>
        <inertial>
            <origin rpy="0 0 0" xyz="-5.317e-02 1.04419e-01 2.7454e-02" />
            <mass value="3.587895" />
            <inertia ixx="0.025853" ixy="0.007796" ixz="-0.001332" iyy="0.019552" iyz="0.008641" izz="0.028323" />
        </inertial>
    </link>
    <!-- sub-link defining coarse geometries of real robot's internal self-collision -->
    <link name="panda_link4_sc" />
    <!-- fixed joint between both sub-links -->
    <joint name="panda_link4_sc_joint" type="fixed">
        <origin rpy="0 0 0" />
        <parent link="panda_link4" />
        <child link="panda_link4_sc" />
    </joint>
    <joint name="panda_joint4" type="revolute">
        <origin rpy="1.5707963267948966 0 0" xyz="0.0825 0 0" />
        <parent link="panda_link3" />
        <child link="panda_link4" />
        <axis xyz="0 0 1" />
        <limit effort="87.0" lower="-3.0718" upper="-0.0698" velocity="2.175" />
        <safety_controller k_position="100.0" k_velocity="40.0" soft_lower_limit="-3.0718" soft_upper_limit="-0.0698" />
        <dynamics D="1" K="7000" damping="0.003" friction="0.0" mu_coulomb="0" mu_viscous="16" />
    </joint>
    <!-- sub-link defining detailed meshes for collision with environment -->
    <link name="panda_link5">
        <visual>
            <geometry>
                <mesh filename="package://franka_description/meshes/visual/link5.dae" />
            </geometry>
        </visual>
        <collision>
            <geometry>
                <mesh filename="package://franka_description/meshes/collision/link5.stl" />
            </geometry>
        </collision>
        <inertial>
            <origin rpy="0 0 0" xyz="-1.1953e-02 4.1065e-02 -3.8437e-02" />
            <mass value="1.225946" />
            <inertia ixx="0.035549" ixy="-0.002117" ixz="-0.004037" iyy="0.029474" iyz="0.000229" izz="0.008627" />
        </inertial>
    </link>
    <!-- sub-link defining coarse geometries of real robot's internal self-collision -->
    <link name="panda_link5_sc" />
    <!-- fixed joint between both sub-links -->
    <joint name="panda_link5_sc_joint" type="fixed">
        <origin rpy="0 0 0" />
        <parent link="panda_link5" />
        <child link="panda_link5_sc" />
    </joint>
    <joint name="panda_joint5" type="revolute">
        <origin rpy="-1.5707963267948966 0 0" xyz="-0.0825 0.384 0" />
        <parent link="panda_link4" />
        <child link="panda_link5" />
        <axis xyz="0 0 1" />
        <limit effort="12.0" lower="-2.8973" upper="2.8973" velocity="2.61" />
        <safety_controller k_position="100.0" k_velocity="40.0" soft_lower_limit="-2.8973" soft_upper_limit="2.8973" />
        <dynamics D="1" K="7000" damping="0.003" friction="0.0" mu_coulomb="0" mu_viscous="16" />
    </joint>
    <!-- sub-link defining detailed meshes for collision with environment -->
    <link name="panda_link6">
        <visual>
            <geometry>
                <mesh filename="package://franka_description/meshes/visual/link6.dae" />
            </geometry>
        </visual>
        <collision>
            <geometry>
                <mesh filename="package://franka_description/meshes/collision/link6.stl" />
            </geometry>
        </collision>
        <inertial>
            <origin rpy="0 0 0" xyz="6.0149e-02 -1.4117e-02 -1.0517e-02" />
            <mass value="1.666555" />
            <inertia ixx="0.001964" ixy="0.000109" ixz="-0.001158" iyy="0.004354" iyz="0.000341" izz="0.005433" />
        </inertial>
    </link>
    <!-- sub-link defining coarse geometries of real robot's internal self-collision -->
    <link name="panda_link6_sc" />
    <!-- fixed joint between both sub-links -->
    <joint name="panda_link6_sc_joint" type="fixed">
        <origin rpy="0 0 0" />
        <parent link="panda_link6" />
        <child link="panda_link6_sc" />
    </joint>
    <joint name="panda_joint6" type="revolute">
        <origin rpy="1.5707963267948966 0 0" xyz="0 0 0" />
        <parent link="panda_link5" />
        <child link="panda_link6" />
        <axis xyz="0 0 1" />
        <limit effort="12.0" lower="-0.0175" upper="3.7525" velocity="2.61" />
        <safety_controller k_position="100.0" k_velocity="40.0" soft_lower_limit="-0.0175" soft_upper_limit="3.7525" />
        <dynamics D="1" K="7000" damping="0.003" friction="0.0" mu_coulomb="0" mu_viscous="16" />
    </joint>
    <!-- sub-link defining detailed meshes for collision with environment -->
    <link name="panda_link7">
        <visual>
            <geometry>
                <mesh filename="package://franka_description/meshes/visual/link7.dae" />
            </geometry>
        </visual>
        <collision>
            <geometry>
                <mesh filename="package://franka_description/meshes/collision/link7.stl" />
            </geometry>
        </collision>
        <inertial>
            <origin rpy="0 0 0" xyz="1.0517e-02 -4.252e-03 6.1597e-02" />
            <mass value="0.735522" />
            <inertia ixx="0.012516" ixy="-0.000428" ixz="-0.001196" iyy="0.010027" iyz="-0.000741" izz="0.004815" />
        </inertial>
    </link>
    <!-- sub-link defining coarse geometries of real robot's internal self-collision -->
    <link name="panda_link7_sc" />
    <!-- fixed joint between both sub-links -->
    <joint name="panda_link7_sc_joint" type="fixed">
        <origin rpy="0 0 0.7853981633974483" />
        <parent link="panda_link7" />
        <child link="panda_link7_sc" />
    </joint>
    <joint name="panda_joint7" type="revolute">
        <origin rpy="1.5707963267948966 0 0" xyz="0.088 0 0" />
        <parent link="panda_link6" />
        <child link="panda_link7" />
        <axis xyz="0 0 1" />
        <limit effort="12.0" lower="-2.8973" upper="2.8973" velocity="2.61" />
        <safety_controller k_position="100.0" k_velocity="40.0" soft_lower_limit="-2.8973" soft_upper_limit="2.8973" />
        <dynamics D="1" K="7000" damping="0.003" friction="0.0" mu_coulomb="0" mu_viscous="16" />
    </joint>
    <link name="panda_link8" />
    <joint name="panda_joint8" type="fixed">
        <origin rpy="0 0 0" xyz="0 0 0.107" />
        <parent link="panda_link7" />
        <child link="panda_link8" />
    </joint>
    <joint name="panda_hand_joint" type="fixed">
        <parent link="panda_link8" />
        <child link="panda_hand" />
        <origin rpy="0 0 -0.7853981633974483" xyz="0 0 0" />
    </joint>
    <!-- sub-link defining detailed meshes for collision with environment -->
    <link name="panda_hand">
        <visual>
            <geometry>
                <mesh filename="package://franka_description/meshes/visual/hand.dae" />
            </geometry>
        </visual>
        <collision>
            <geometry>
                <mesh filename="package://franka_description/meshes/collision/hand.stl" />
            </geometry>
        </collision>
        <inertial>
            <origin rpy="0 0 0" xyz="-0.01 0 0.03" />
            <mass value="0.73" />
            <inertia ixx="0.001" ixy="0" ixz="0" iyy="0.0025" iyz="0" izz="0.0017" />
        </inertial>
    </link>
    <!-- sub-link defining coarse geometries of real robot's internal self-collision -->
    <link name="panda_hand_sc" />
    <!-- fixed joint between both sub-links -->
    <joint name="panda_hand_sc_joint" type="fixed">
        <origin rpy="0 0 0" />
        <parent link="panda_hand" />
        <child link="panda_hand_sc" />
    </joint>
    <!-- Define the hand_tcp frame -->
    <link name="panda_hand_tcp" />
    <joint name="panda_hand_tcp_joint" type="fixed">
        <origin rpy="0 0 0" xyz="0 0 0.1034" />
        <parent link="panda_hand" />
        <child link="panda_hand_tcp" />
    </joint>
    <link name="panda_leftfinger">
        <visual>
            <geometry>
                <mesh filename="package://franka_description/meshes/visual/finger.dae" />
            </geometry>
        </visual>
        <!-- screw mount -->
        <collision>
            <origin rpy="0 0 0" xyz="0 18.5e-3 11e-3" />
            <geometry>
                <box size="22e-3 15e-3 20e-3" />
            </geometry>
        </collision>
        <!-- cartriage sledge -->
        <collision>
            <origin rpy="0 0 0" xyz="0 6.8e-3 2.2e-3" />
            <geometry>
                <box size="22e-3 8.8e-3 3.8e-3" />
            </geometry>
        </collision>
        <!-- diagonal finger -->
        <collision>
            <origin rpy="0.5235987755982988 0 0" xyz="0 15.9e-3 28.35e-3" />
            <geometry>
                <box size="17.5e-3 7e-3 23.5e-3" />
            </geometry>
        </collision>
        <!-- rubber tip with which to grasp -->
        <collision>
            <origin rpy="0 0 0" xyz="0 7.58e-3 45.25e-3" />
            <geometry>
                <box size="17.5e-3 15.2e-3 18.5e-3" />
            </geometry>
        </collision>
        <inertial>
            <origin rpy="0 0 0" xyz="0 0 0" />
            <mass value="0.015" />
            <inertia ixx="2.3749999999999997e-06" ixy="0" ixz="0" iyy="2.3749999999999997e-06" iyz="0" izz="7.5e-07" />
        </inertial>
    </link>
    <link name="panda_rightfinger">
        <visual>
            <origin rpy="0 0 3.141592653589793" xyz="0 0 0" />
            <geometry>
                <mesh filename="package://franka_description/meshes/visual/finger.dae" />
            </geometry>
        </visual>
        <!-- screw mount -->
        <collision>
            <origin rpy="0 0 0" xyz="0 -18.5e-3 11e-3" />
            <geometry>
                <box size="22e-3 15e-3 20e-3" />
            </geometry>
        </collision>
        <!-- cartriage sledge -->
        <collision>
            <origin rpy="0 0 0" xyz="0 -6.8e-3 2.2e-3" />
            <geometry>
                <box size="22e-3 8.8e-3 3.8e-3" />
            </geometry>
        </collision>
        <!-- diagonal finger -->
        <collision>
            <origin rpy="-0.5235987755982988 0 0" xyz="0 -15.9e-3 28.35e-3" />
            <geometry>
                <box size="17.5e-3 7e-3 23.5e-3" />
            </geometry>
        </collision>
        <!-- rubber tip with which to grasp -->
        <collision>
            <origin rpy="0 0 0" xyz="0 -7.58e-3 45.25e-3" />
            <geometry>
                <box size="17.5e-3 15.2e-3 18.5e-3" />
            </geometry>
        </collision>
        <inertial>
            <origin rpy="0 0 0" xyz="0 0 0" />
            <mass value="0.015" />
            <inertia ixx="2.3749999999999997e-06" ixy="0" ixz="0" iyy="2.3749999999999997e-06" iyz="0" izz="7.5e-07" />
        </inertial>
    </link>
    <joint name="panda_finger_joint1" type="prismatic">
        <parent link="panda_hand" />
        <child link="panda_leftfinger" />
        <origin rpy="0 0 0" xyz="0 0 0.0584" />
        <axis xyz="0 1 0" />
        <limit effort="100" lower="0.0" upper="0.04" velocity="0.2" />
        <dynamics damping="0.3" />
    </joint>
    <joint name="panda_finger_joint2" type="prismatic">
        <parent link="panda_hand" />
        <child link="panda_rightfinger" />
        <origin rpy="0 0 0" xyz="0 0 0.0584" />
        <axis xyz="0 -1 0" />
        <limit effort="100" lower="0.0" upper="0.04" velocity="0.2" />
        <mimic joint="panda_finger_joint1" />
        <dynamics damping="0.3" />
    </joint>
    <material name="aluminum">
        <color rgba="0.5 0.5 0.5 1" />
    </material>
    <material name="plastic">
        <color rgba="0.1 0.1 0.1 1" />
    </material>
    <gazebo reference="wrist_camera_link">
        <sensor name="wrist_camera" type="depth">
            <always_on>true</always_on>
            <update_rate>30</update_rate>
            <camera>
                <horizontal_fov>0.976899239</horizontal_fov>
                <image>
                    <format>R8G8B8</format>
                    <width>640</width>
                    <height>480</height>
                </image>
                <clip>
                    <near>0.1</near>
                    <far>10</far>
                </clip>
            </camera>
            <plugin filename="libgazebo_ros_openni_kinect.so" name="camera_plugin">
                <alwaysOn>true</alwaysOn>
                <!-- <baseline>0.2</baseline> -->
                <updateRate>0.0</updateRate>
                <cameraName>wrist_camera</cameraName>
                <imageTopicName>/wrist_camera/color/image_raw</imageTopicName>
                <cameraInfoTopicName>/wrist_camera/color/camera_info</cameraInfoTopicName>
                <depthImageTopicName>/wrist_camera/depth/image_rect_raw</depthImageTopicName>
                <depthImageCameraInfoTopicName>/wrist_camera/depth/camera_info</depthImageCameraInfoTopicName>
                <pointCloudTopicName>/wrist_camera/depth/color/points</pointCloudTopicName>
                <frameName>wrist_camera_depth_optical_frame</frameName>
                <pointCloudCutoff>0.1</pointCloudCutoff>
                <pointCloudCutoffMax>10</pointCloudCutoffMax>
                <distortionK1>0</distortionK1>
                <distortionK2>0</distortionK2>
                <distortionK3>0</distortionK3>
                <distortionT1>0</distortionT1>
                <distortionT2>0</distortionT2>
            </plugin>
        </sensor>
    </gazebo>
    <!-- camera body, with origin at bottom screw mount -->
    <joint name="wrist_camera_joint" type="fixed">
        <origin rpy="-1.117916 -1.5611535 -2.8045692" xyz="0.03062033586096833 -0.025020246008959142 0.04595534939725603" />
        <parent link="panda_link8" />
        <child link="wrist_camera_bottom_screw_frame" />
    </joint>
    <link name="wrist_camera_bottom_screw_frame" />
    <joint name="wrist_camera_link_joint" type="fixed">
        <origin rpy="0 0 0" xyz="0.010600000000000002 0.0175 0.0125" />
        <parent link="wrist_camera_bottom_screw_frame" />
        <child link="wrist_camera_link" />
    </joint>
    <link name="wrist_camera_link">
        <visual>
            <!-- the mesh origin is at front plate in between the two infrared camera axes -->
            <origin rpy="1.5707963267948966 0 1.5707963267948966" xyz="0.0043 -0.0175 0" />
            <geometry>
                <mesh filename="package://realsense2_description/meshes/d435.dae" />
            </geometry>
        </visual>
        <collision>
            <origin rpy="0 0 0" xyz="0 -0.0175 0" />
            <geometry>
                <box size="0.02505 0.09 0.025" />
            </geometry>
        </collision>
        <inertial>
            <!-- The following are not reliable values, and should not be used for modeling -->
            <mass value="0.072" />
            <origin xyz="0 0 0" rpy="0 0 0" />
            <inertia ixx="0.003881243" ixy="0.0" ixz="0.0" iyy="0.000498940" iyz="0.0" izz="0.003879257" />
        </inertial>
    </link>
    <!-- camera depth joints and links -->
    <joint name="wrist_camera_depth_joint" type="fixed">
        <origin rpy="0 0 0" xyz="0 0 0" />
        <parent link="wrist_camera_link" />
        <child link="wrist_camera_depth_frame" />
    </joint>
    <link name="wrist_camera_depth_frame" />
    <joint name="wrist_camera_depth_optical_joint" type="fixed">
        <origin rpy="-1.5707963267948966 0 -1.5707963267948966" xyz="0 0 0" />
        <parent link="wrist_camera_depth_frame" />
        <child link="wrist_camera_depth_optical_frame" />
    </joint>
    <link name="wrist_camera_depth_optical_frame" />
    <!-- camera left IR joints and links -->
    <joint name="wrist_camera_infra1_joint" type="fixed">
        <origin rpy="0 0 0" xyz="0 0.0 0" />
        <parent link="wrist_camera_link" />
        <child link="wrist_camera_infra1_frame" />
    </joint>
    <link name="wrist_camera_infra1_frame" />
    <joint name="wrist_camera_infra1_optical_joint" type="fixed">
        <origin rpy="-1.5707963267948966 0 -1.5707963267948966" xyz="0 0 0" />
        <parent link="wrist_camera_infra1_frame" />
        <child link="wrist_camera_infra1_optical_frame" />
    </joint>
    <link name="wrist_camera_infra1_optical_frame" />
    <!-- camera right IR joints and links -->
    <joint name="wrist_camera_infra2_joint" type="fixed">
        <origin rpy="0 0 0" xyz="0 -0.05 0" />
        <parent link="wrist_camera_link" />
        <child link="wrist_camera_infra2_frame" />
    </joint>
    <link name="wrist_camera_infra2_frame" />
    <joint name="wrist_camera_infra2_optical_joint" type="fixed">
        <origin rpy="-1.5707963267948966 0 -1.5707963267948966" xyz="0 0 0" />
        <parent link="wrist_camera_infra2_frame" />
        <child link="wrist_camera_infra2_optical_frame" />
    </joint>
    <link name="wrist_camera_infra2_optical_frame" />
    <!-- camera color joints and links -->
    <joint name="wrist_camera_color_joint" type="fixed">
        <origin rpy="0 0 0" xyz="0 0.015 0" />
        <parent link="wrist_camera_link" />
        <child link="wrist_camera_color_frame" />
    </joint>
    <link name="wrist_camera_color_frame" />
    <joint name="wrist_camera_color_optical_joint" type="fixed">
        <origin rpy="-1.5707963267948966 0 -1.5707963267948966" xyz="0 0 0" />
        <parent link="wrist_camera_color_frame" />
        <child link="wrist_camera_color_optical_frame" />
    </joint>
    <link name="wrist_camera_color_optical_frame" />
    <joint name="franka_mount_link_joint" type="fixed">
        <origin rpy="0 0 0" xyz="0 0 0" />
        <parent link="franka_mount_link" />
        <child link="panda_link0" />
    </joint>
    <gazebo reference="panda_joint1">
        <!-- Needed for ODE to output external wrenches on joints -->
        <provideFeedback>true</provideFeedback>
    </gazebo>
    <transmission name="panda_joint1_transmission">
        <type>transmission_interface/SimpleTransmission</type>
        <joint name="panda_joint1">
            <hardwareInterface>hardware_interface/PositionJointInterface</hardwareInterface>
        </joint>
        <actuator name="panda_joint1_motor">
            <hardwareInterface>hardware_interface/PositionJointInterface</hardwareInterface>
        </actuator>
    </transmission>
    <gazebo reference="panda_joint2">
        <!-- Needed for ODE to output external wrenches on joints -->
        <provideFeedback>true</provideFeedback>
    </gazebo>
    <transmission name="panda_joint2_transmission">
        <type>transmission_interface/SimpleTransmission</type>
        <joint name="panda_joint2">
            <hardwareInterface>hardware_interface/PositionJointInterface</hardwareInterface>
        </joint>
        <actuator name="panda_joint2_motor">
            <hardwareInterface>hardware_interface/PositionJointInterface</hardwareInterface>
        </actuator>
    </transmission>
    <gazebo reference="panda_joint3">
        <!-- Needed for ODE to output external wrenches on joints -->
        <provideFeedback>true</provideFeedback>
    </gazebo>
    <transmission name="panda_joint3_transmission">
        <type>transmission_interface/SimpleTransmission</type>
        <joint name="panda_joint3">
            <hardwareInterface>hardware_interface/PositionJointInterface</hardwareInterface>
        </joint>
        <actuator name="panda_joint3_motor">
            <hardwareInterface>hardware_interface/PositionJointInterface</hardwareInterface>
        </actuator>
    </transmission>
    <gazebo reference="panda_joint4">
        <!-- Needed for ODE to output external wrenches on joints -->
        <provideFeedback>true</provideFeedback>
    </gazebo>
    <transmission name="panda_joint4_transmission">
        <type>transmission_interface/SimpleTransmission</type>
        <joint name="panda_joint4">
            <hardwareInterface>hardware_interface/PositionJointInterface</hardwareInterface>
        </joint>
        <actuator name="panda_joint4_motor">
            <hardwareInterface>hardware_interface/PositionJointInterface</hardwareInterface>
        </actuator>
    </transmission>
    <gazebo reference="panda_joint5">
        <!-- Needed for ODE to output external wrenches on joints -->
        <provideFeedback>true</provideFeedback>
    </gazebo>
    <transmission name="panda_joint5_transmission">
        <type>transmission_interface/SimpleTransmission</type>
        <joint name="panda_joint5">
            <hardwareInterface>hardware_interface/PositionJointInterface</hardwareInterface>
        </joint>
        <actuator name="panda_joint5_motor">
            <hardwareInterface>hardware_interface/PositionJointInterface</hardwareInterface>
        </actuator>
    </transmission>
    <gazebo reference="panda_joint6">
        <!-- Needed for ODE to output external wrenches on joints -->
        <provideFeedback>true</provideFeedback>
    </gazebo>
    <transmission name="panda_joint6_transmission">
        <type>transmission_interface/SimpleTransmission</type>
        <joint name="panda_joint6">
            <hardwareInterface>hardware_interface/PositionJointInterface</hardwareInterface>
        </joint>
        <actuator name="panda_joint6_motor">
            <hardwareInterface>hardware_interface/PositionJointInterface</hardwareInterface>
        </actuator>
    </transmission>
    <gazebo reference="panda_joint7">
        <!-- Needed for ODE to output external wrenches on joints -->
        <provideFeedback>true</provideFeedback>
    </gazebo>
    <transmission name="panda_joint7_transmission">
        <type>transmission_interface/SimpleTransmission</type>
        <joint name="panda_joint7">
            <hardwareInterface>hardware_interface/PositionJointInterface</hardwareInterface>
        </joint>
        <actuator name="panda_joint7_motor">
            <hardwareInterface>hardware_interface/PositionJointInterface</hardwareInterface>
        </actuator>
    </transmission>
    <gazebo reference="panda_joint1">
        <!-- Needed for ODE to output external wrenches on joints -->
        <provideFeedback>true</provideFeedback>
    </gazebo>
    <transmission name="panda_joint1_transmission">
        <type>transmission_interface/SimpleTransmission</type>
        <joint name="panda_joint1">
            <hardwareInterface>hardware_interface/VelocityJointInterface</hardwareInterface>
        </joint>
        <actuator name="panda_joint1_motor">
            <hardwareInterface>hardware_interface/VelocityJointInterface</hardwareInterface>
        </actuator>
    </transmission>
    <gazebo reference="panda_joint2">
        <!-- Needed for ODE to output external wrenches on joints -->
        <provideFeedback>true</provideFeedback>
    </gazebo>
    <transmission name="panda_joint2_transmission">
        <type>transmission_interface/SimpleTransmission</type>
        <joint name="panda_joint2">
            <hardwareInterface>hardware_interface/VelocityJointInterface</hardwareInterface>
        </joint>
        <actuator name="panda_joint2_motor">
            <hardwareInterface>hardware_interface/VelocityJointInterface</hardwareInterface>
        </actuator>
    </transmission>
    <gazebo reference="panda_joint3">
        <!-- Needed for ODE to output external wrenches on joints -->
        <provideFeedback>true</provideFeedback>
    </gazebo>
    <transmission name="panda_joint3_transmission">
        <type>transmission_interface/SimpleTransmission</type>
        <joint name="panda_joint3">
            <hardwareInterface>hardware_interface/VelocityJointInterface</hardwareInterface>
        </joint>
        <actuator name="panda_joint3_motor">
            <hardwareInterface>hardware_interface/VelocityJointInterface</hardwareInterface>
        </actuator>
    </transmission>
    <gazebo reference="panda_joint4">
        <!-- Needed for ODE to output external wrenches on joints -->
        <provideFeedback>true</provideFeedback>
    </gazebo>
    <transmission name="panda_joint4_transmission">
        <type>transmission_interface/SimpleTransmission</type>
        <joint name="panda_joint4">
            <hardwareInterface>hardware_interface/VelocityJointInterface</hardwareInterface>
        </joint>
        <actuator name="panda_joint4_motor">
            <hardwareInterface>hardware_interface/VelocityJointInterface</hardwareInterface>
        </actuator>
    </transmission>
    <gazebo reference="panda_joint5">
        <!-- Needed for ODE to output external wrenches on joints -->
        <provideFeedback>true</provideFeedback>
    </gazebo>
    <transmission name="panda_joint5_transmission">
        <type>transmission_interface/SimpleTransmission</type>
        <joint name="panda_joint5">
            <hardwareInterface>hardware_interface/VelocityJointInterface</hardwareInterface>
        </joint>
        <actuator name="panda_joint5_motor">
            <hardwareInterface>hardware_interface/VelocityJointInterface</hardwareInterface>
        </actuator>
    </transmission>
    <gazebo reference="panda_joint6">
        <!-- Needed for ODE to output external wrenches on joints -->
        <provideFeedback>true</provideFeedback>
    </gazebo>
    <transmission name="panda_joint6_transmission">
        <type>transmission_interface/SimpleTransmission</type>
        <joint name="panda_joint6">
            <hardwareInterface>hardware_interface/VelocityJointInterface</hardwareInterface>
        </joint>
        <actuator name="panda_joint6_motor">
            <hardwareInterface>hardware_interface/VelocityJointInterface</hardwareInterface>
        </actuator>
    </transmission>
    <gazebo reference="panda_joint7">
        <!-- Needed for ODE to output external wrenches on joints -->
        <provideFeedback>true</provideFeedback>
    </gazebo>
    <transmission name="panda_joint7_transmission">
        <type>transmission_interface/SimpleTransmission</type>
        <joint name="panda_joint7">
            <hardwareInterface>hardware_interface/VelocityJointInterface</hardwareInterface>
        </joint>
        <actuator name="panda_joint7_motor">
            <hardwareInterface>hardware_interface/VelocityJointInterface</hardwareInterface>
        </actuator>
    </transmission>
    <gazebo reference="panda_joint1">
        <!-- Needed for ODE to output external wrenches on joints -->
        <provideFeedback>true</provideFeedback>
    </gazebo>
    <transmission name="panda_joint1_transmission">
        <type>transmission_interface/SimpleTransmission</type>
        <joint name="panda_joint1">
            <hardwareInterface>hardware_interface/EffortJointInterface</hardwareInterface>
        </joint>
        <actuator name="panda_joint1_motor">
            <hardwareInterface>hardware_interface/EffortJointInterface</hardwareInterface>
            <mechanicalReduction>1</mechanicalReduction>
        </actuator>
    </transmission>
    <gazebo reference="panda_joint2">
        <!-- Needed for ODE to output external wrenches on joints -->
        <provideFeedback>true</provideFeedback>
    </gazebo>
    <transmission name="panda_joint2_transmission">
        <type>transmission_interface/SimpleTransmission</type>
        <joint name="panda_joint2">
            <hardwareInterface>hardware_interface/EffortJointInterface</hardwareInterface>
        </joint>
        <actuator name="panda_joint2_motor">
            <hardwareInterface>hardware_interface/EffortJointInterface</hardwareInterface>
            <mechanicalReduction>1</mechanicalReduction>
        </actuator>
    </transmission>
    <gazebo reference="panda_joint3">
        <!-- Needed for ODE to output external wrenches on joints -->
        <provideFeedback>true</provideFeedback>
    </gazebo>
    <transmission name="panda_joint3_transmission">
        <type>transmission_interface/SimpleTransmission</type>
        <joint name="panda_joint3">
            <hardwareInterface>hardware_interface/EffortJointInterface</hardwareInterface>
        </joint>
        <actuator name="panda_joint3_motor">
            <hardwareInterface>hardware_interface/EffortJointInterface</hardwareInterface>
            <mechanicalReduction>1</mechanicalReduction>
        </actuator>
    </transmission>
    <gazebo reference="panda_joint4">
        <!-- Needed for ODE to output external wrenches on joints -->
        <provideFeedback>true</provideFeedback>
    </gazebo>
    <transmission name="panda_joint4_transmission">
        <type>transmission_interface/SimpleTransmission</type>
        <joint name="panda_joint4">
            <hardwareInterface>hardware_interface/EffortJointInterface</hardwareInterface>
        </joint>
        <actuator name="panda_joint4_motor">
            <hardwareInterface>hardware_interface/EffortJointInterface</hardwareInterface>
            <mechanicalReduction>1</mechanicalReduction>
        </actuator>
    </transmission>
    <gazebo reference="panda_joint5">
        <!-- Needed for ODE to output external wrenches on joints -->
        <provideFeedback>true</provideFeedback>
    </gazebo>
    <transmission name="panda_joint5_transmission">
        <type>transmission_interface/SimpleTransmission</type>
        <joint name="panda_joint5">
            <hardwareInterface>hardware_interface/EffortJointInterface</hardwareInterface>
        </joint>
        <actuator name="panda_joint5_motor">
            <hardwareInterface>hardware_interface/EffortJointInterface</hardwareInterface>
            <mechanicalReduction>1</mechanicalReduction>
        </actuator>
    </transmission>
    <gazebo reference="panda_joint6">
        <!-- Needed for ODE to output external wrenches on joints -->
        <provideFeedback>true</provideFeedback>
    </gazebo>
    <transmission name="panda_joint6_transmission">
        <type>transmission_interface/SimpleTransmission</type>
        <joint name="panda_joint6">
            <hardwareInterface>hardware_interface/EffortJointInterface</hardwareInterface>
        </joint>
        <actuator name="panda_joint6_motor">
            <hardwareInterface>hardware_interface/EffortJointInterface</hardwareInterface>
            <mechanicalReduction>1</mechanicalReduction>
        </actuator>
    </transmission>
    <gazebo reference="panda_joint7">
        <!-- Needed for ODE to output external wrenches on joints -->
        <provideFeedback>true</provideFeedback>
    </gazebo>
    <transmission name="panda_joint7_transmission">
        <type>transmission_interface/SimpleTransmission</type>
        <joint name="panda_joint7">
            <hardwareInterface>hardware_interface/EffortJointInterface</hardwareInterface>
        </joint>
        <actuator name="panda_joint7_motor">
            <hardwareInterface>hardware_interface/EffortJointInterface</hardwareInterface>
            <mechanicalReduction>1</mechanicalReduction>
        </actuator>
    </transmission>
    <transmission name="panda_franka_state">
        <type>franka_hw/FrankaStateInterface</type>
        <joint name="panda_joint1">
            <hardwareInterface>franka_hw/FrankaStateInterface</hardwareInterface>
        </joint>
        <joint name="panda_joint2">
            <hardwareInterface>franka_hw/FrankaStateInterface</hardwareInterface>
        </joint>
        <joint name="panda_joint3">
            <hardwareInterface>franka_hw/FrankaStateInterface</hardwareInterface>
        </joint>
        <joint name="panda_joint4">
            <hardwareInterface>franka_hw/FrankaStateInterface</hardwareInterface>
        </joint>
        <joint name="panda_joint5">
            <hardwareInterface>franka_hw/FrankaStateInterface</hardwareInterface>
        </joint>
        <joint name="panda_joint6">
            <hardwareInterface>franka_hw/FrankaStateInterface</hardwareInterface>
        </joint>
        <joint name="panda_joint7">
            <hardwareInterface>franka_hw/FrankaStateInterface</hardwareInterface>
        </joint>
        <actuator name="panda_motor1">
            <hardwareInterface>franka_hw/FrankaStateInterface</hardwareInterface>
        </actuator>
        <actuator name="panda_motor2">
            <hardwareInterface>franka_hw/FrankaStateInterface</hardwareInterface>
        </actuator>
        <actuator name="panda_motor3">
            <hardwareInterface>franka_hw/FrankaStateInterface</hardwareInterface>
        </actuator>
        <actuator name="panda_motor4">
            <hardwareInterface>franka_hw/FrankaStateInterface</hardwareInterface>
        </actuator>
        <actuator name="panda_motor5">
            <hardwareInterface>franka_hw/FrankaStateInterface</hardwareInterface>
        </actuator>
        <actuator name="panda_motor6">
            <hardwareInterface>franka_hw/FrankaStateInterface</hardwareInterface>
        </actuator>
        <actuator name="panda_motor7">
            <hardwareInterface>franka_hw/FrankaStateInterface</hardwareInterface>
        </actuator>
    </transmission>
    <transmission name="panda_franka_model">
        <type>franka_hw/FrankaModelInterface</type>
        <joint name="panda_joint1">
            <role>root</role>
            <hardwareInterface>franka_hw/FrankaModelInterface</hardwareInterface>
        </joint>
        <joint name="panda_joint8">
            <role>tip</role>
            <hardwareInterface>franka_hw/FrankaModelInterface</hardwareInterface>
        </joint>
        <actuator name="panda_joint1_motor_root">
            <hardwareInterface>franka_hw/FrankaModelInterface</hardwareInterface>
        </actuator>
        <actuator name="panda_joint8_motor_tip">
            <hardwareInterface>franka_hw/FrankaModelInterface</hardwareInterface>
        </actuator>
    </transmission>
    <gazebo reference="panda_finger_joint1">
        <!-- Needed for ODE to output external wrenches on joints -->
        <provideFeedback>true</provideFeedback>
    </gazebo>
    <transmission name="panda_finger_joint1_transmission">
        <type>transmission_interface/SimpleTransmission</type>
        <joint name="panda_finger_joint1">
            <hardwareInterface>hardware_interface/EffortJointInterface</hardwareInterface>
        </joint>
        <actuator name="panda_finger_joint1_motor">
            <hardwareInterface>hardware_interface/EffortJointInterface</hardwareInterface>
            <mechanicalReduction>1</mechanicalReduction>
        </actuator>
    </transmission>
    <gazebo reference="panda_finger_joint2">
        <!-- Needed for ODE to output external wrenches on joints -->
        <provideFeedback>true</provideFeedback>
    </gazebo>
    <transmission name="panda_finger_joint2_transmission">
        <type>transmission_interface/SimpleTransmission</type>
        <joint name="panda_finger_joint2">
            <hardwareInterface>hardware_interface/EffortJointInterface</hardwareInterface>
        </joint>
        <actuator name="panda_finger_joint2_motor">
            <hardwareInterface>hardware_interface/EffortJointInterface</hardwareInterface>
            <mechanicalReduction>1</mechanicalReduction>
        </actuator>
    </transmission>
    <gazebo reference="panda_leftfinger">
        <collision>
            <max_contacts>10</max_contacts>
            <surface>
                <contact>
                    <ode>
                        <!-- These two parameter need application specific tuning. -->
                        <!-- Usually you want no "snap out" velocity and a generous -->
                        <!-- penetration depth to keep the grasping stable -->
                        <max_vel>0</max_vel>
                        <min_depth>0.001</min_depth>
                    </ode>
                </contact>
                <friction>
                    <ode>
                        <mu>1.13</mu>
                        <mu2>1.13</mu2>
                    </ode>
                </friction>
                <bounce />
            </surface>
        </collision>
    </gazebo>
    <gazebo reference="panda_rightfinger">
        <collision>
            <max_contacts>10</max_contacts>
            <surface>
                <contact>
                    <ode>
                        <!-- These two parameter need application specific tuning. -->
                        <!-- Usually you want no "snap out" velocity and a generous -->
                        <!-- penetration depth to keep the grasping stable -->
                        <max_vel>0</max_vel>
                        <min_depth>0.001</min_depth>
                    </ode>
                </contact>
                <friction>
                    <ode>
                        <mu>1.13</mu>
                        <mu2>1.13</mu2>
                    </ode>
                </friction>
                <bounce />
            </surface>
        </collision>
    </gazebo>
    <gazebo>
        <plugin filename="libgazebo_ros_control.so" name="gazebo_ros_control">
            <controlPeriod>0.001</controlPeriod>
            <robotSimType>franka_gazebo/FrankaHWSim</robotSimType>
        </plugin>
        <self_collide>true</self_collide>
    </gazebo>
</robot>
