<?xml version="1.0" encoding="utf-8"?>
<robot xmlns:xacro="http://www.ros.org/wiki/xacro" name="superur5e">

  <!-- MPC Arguments -->
  <xacro:arg name="mpc_model" default="false"/>

  <!-- parameters -->
  <xacro:arg name="joint_limit_params" default=""/>
  <xacro:arg name="kinematics_params" default=""/>
  <xacro:arg name="physical_params" default=""/>
  <xacro:arg name="visual_params" default=""/>
  <xacro:arg name="transmission_hw_interface" default="hardware_interface/PositionJointInterface"/>
  <xacro:arg name="safety_limits" default="false"/>
  <xacro:arg name="safety_pos_margin" default="0.15"/>
  <xacro:arg name="safety_k_position" default="20"/>

  <!--<xacro:if value="$(arg mpc_model)">-->
    <link name="world" />
    <joint name="base_prismatic_x" type="prismatic">
      <parent link="world" />
      <child link="base_x" />
      <origin xyz="0 0 0" rpy="0 0 0"/>
      <axis xyz="1 0 0"/>
      <limit effort="0" velocity="0"/>
    </joint>
    <link name="base_x" />
    <joint name="base_prismatic_y" type="prismatic">
      <parent link="base_x" />
      <child link="base_y" />
      <origin xyz="0 0 0" rpy="0 0 0"/>
      <axis xyz="0 1 0"/>
      <limit effort="0" velocity="0"/>
    </joint>
    <link name="base_y" />
    <joint name="base_revolute_theta" type="revolute">
      <parent link="base_y" />
      <child link="base_theta" />
      <origin xyz="0 0 0" rpy="0 0 0"/>
      <axis xyz="0 0 1"/>
      <limit effort="0" velocity="0"/>
    </joint>
    <link name="base_theta" />

    <!-- Rigid fix between Base and UR -->
      <joint name="arm_mount_joint" type="fixed">
        <parent link="base_theta" />
        <child link="base_link" />
        <origin xyz="0 0 0" rpy="0 0 0"/>
      </joint>
  <!--</xacro:if>-->

  <xacro:include filename="$(find ur_description)/urdf/inc/ur5e_macro.xacro"/>
  <xacro:ur5e_robot
    prefix=""
    joint_limits_parameters_file="$(arg joint_limit_params)"
    kinematics_parameters_file="$(arg kinematics_params)"
    physical_parameters_file="$(arg physical_params)"
    visual_parameters_file="$(arg visual_params)"
    transmission_hw_interface="$(arg transmission_hw_interface)"
    safety_limits="$(arg safety_limits)"
    safety_pos_margin="$(arg safety_pos_margin)"
    safety_k_position="$(arg safety_k_position)"/>

</robot>
