<?xml version="1.0" ?>
<!-- =================================================================================== -->
<!-- |    This document was autogenerated by xacro from ../../../moma_description/urdf/superpanda.urdf.xacro | -->
<!-- |    EDITING THIS FILE BY HAND IS NOT RECOMMENDED                                 | -->
<!-- =================================================================================== -->
<robot name="superpanda">
  <!-- Materials -->
  <material name="black">
    <color rgba="0 0 0 1.0"/>
  </material>
  <material name="dark_grey">
    <color rgba="0 0 0 0.6078431372549019 1.0"/>
  </material>
  <material name="blue">
    <color rgba="0 0 0.7843137254901961 1.0"/>
  </material>
  <material name="green">
    <color rgba="0 0.7843137254901961 0 1.0"/>
  </material>
  <material name="grey">
    <color rgba="0.19607843137254902 0.19607843137254902 0.19607843137254902 1.0"/>
  </material>
  <material name="orange">
    <color rgba="1.0 0.4235294117647059 0.0392156862745098 1.0"/>
  </material>
  <material name="brown">
    <color rgba="0.8705882352941177 0.8117647058823529 0.7647058823529411 1.0"/>
  </material>
  <material name="red">
    <color rgba="0.7843137254901961 0 0 1.0"/>
  </material>
  <material name="white">
    <color rgba="1.0 1.0 1.0 1.0"/>
  </material>
  <!-- t265_origin_xyz is the offset to the parent link -->
  <!-- t265_origin_rpy is the fixed axis roll, pitch and yaw angle such that the resulting frame has
       the x axis pointing forward ("out of camera"),
       the y axis pointing left and the z axis pointing upward -->
  <!-- another frame "realsense_t265_odom_frame is created that is in line with the one documented here:
       https://www.intel.com/content/dam/support/us/en/documents/emerging-technologies/intel-realsense-technology/IntelRealSenseTrackingT265Datasheet.pdf -->
  <link name="base_link">
    <collision>
      <origin rpy="0 0 0" xyz="0 0 0"/>
      <geometry>
        <box size="0.605 0.41 0.197"/>
      </geometry>
    </collision>
    <visual>
      <origin rpy="0 0 0" xyz="0 0 0"/>
      <geometry>
        <box size="0.605 0.41 0.197"/>
      </geometry>
      <material name="base_material">
        <color rgba="0.8 0.0 0.1 1.0"/>
      </material>
    </visual>
  </link>
  <link name="top">
    <collision>
      <origin rpy="0 0 0" xyz="-0.07 0 0"/>
      <geometry>
        <!-- <box size="${topLength} ${topWidth} ${topHeight}"/> -->
        <mesh filename="/smb_description/urdf/new_payload/meshes/SMB_step.dae"/>
      </geometry>
    </collision>
    <visual>
      <origin rpy="0 0 0" xyz="0 0 0"/>
      <geometry>
        <!-- <box size="${topLength} ${topWidth} ${topHeight}"/> -->
        <mesh filename="/smb_description/urdf/new_payload/meshes/SMB_step.dae"/>
      </geometry>
    </visual>
  </link>
  <gazebo reference="top">
    <material>Gazebo/Grey</material>
  </gazebo>
  <gazebo reference="base_link">
    <material>Gazebo/Red</material>
  </gazebo>
  <joint name="top_to_base_link" type="fixed">
    <parent link="base_link"/>
    <child link="top"/>
    <!-- <origin xyz="${topXOffset/2.0} 0.0 ${chassisHeight/2.0 + topHeight/2.0}" rpy="0 0 0"/> -->
    <origin rpy="0 0 0" xyz="0.0 0.0 0.0985"/>
  </joint>
  <!-- Fixed joint to add dummy inertia link -->
  <joint name="base_to_base_inertia" type="fixed">
    <parent link="base_link"/>
    <child link="base_inertia"/>
    <origin rpy="0 0 0" xyz="0 0 0"/>
  </joint>
  <!-- Dummy inertia link, because KDL cannot have inertia on the base link -->
  <link name="base_inertia">
    <inertial>
      <origin rpy="0 0 0" xyz="0 0 0"/>
      <mass value="40"/>
      <inertia ixx="0.6896966666666665" ixy="0" ixz="0" iyy="1.3494466666666665" iyz="0" izz="1.3494466666666665"/>
    </inertial>
  </link>
  <joint name="LF_WHEEL_JOINT" type="continuous">
    <parent link="base_link"/>
    <child link="LF_WHEEL"/>
    <origin rpy="-1.5707963267948966 0 0" xyz="0.2159 0.27749999999999997 -0.018500000000000003"/>
    <axis rpy="0 0 0" xyz="0 0 1"/>
    <dynamics damping="1.0" friction="0.0"/>
    <limit effort="100" velocity="10"/>
    <joint_properties damping="0.2" friction="0.2"/>
  </joint>
  <link name="LF_WHEEL">
    <collision>
      <origin rpy="0 0 0" xyz="0 0 0"/>
      <geometry>
        <cylinder length="0.0085" radius="0.145"/>
      </geometry>
    </collision>
    <visual>
      <origin rpy="-1.570796 0 1.570796" xyz="0 0 0"/>
      <geometry>
        <mesh filename="/smb_description/urdf/meshes/wheel.dae"/>
      </geometry>
    </visual>
    <inertial>
      <origin rpy="0 0 0" xyz="0 0 0"/>
      <mass value="5"/>
      <inertia ixx="0.02929166666666666" ixy="0" ixz="0" iyy="0.02929166666666666" iyz="0" izz="0.0525625"/>
    </inertial>
  </link>
  <gazebo reference="LF_WHEEL">
    <mu1 value="0.5"/>
    <mu2 value="0.5"/>
    <fdir1 value="1 0 0"/>
    <kp>10000000.0</kp>
    <kd>1.0</kd>
    <minDepth>0.005</minDepth>
    <maxVel>100.0</maxVel>
    <material>Gazebo/DarkGrey</material>
  </gazebo>
  <transmission name="LF_WHEEL_TRANS">
    <type>transmission_interface/SimpleTransmission</type>
    <joint name="LF_WHEEL_JOINT">
      <hardwareInterface>hardware_interface/VelocityJointInterface</hardwareInterface>
      <!--    <hardwareInterface>hardware_interface/EffortJointInterface</hardwareInterface>
                <hardwareInterface>hardware_interface/PositionJointInterface</hardwareInterface> -->
    </joint>
    <actuator name="LF_WHEEL_ACTUATOR">
      <hardwareInterface>hardware_interface/VelocityJointInterface</hardwareInterface>
      <!-- <hardwareInterface>hardware_interface/EffortJointInterface</hardwareInterface>
                <hardwareInterface>hardware_interface/PositionJointInterface</hardwareInterface> -->
      <mechanicalReduction>1</mechanicalReduction>
    </actuator>
  </transmission>
  <joint name="RF_WHEEL_JOINT" type="continuous">
    <parent link="base_link"/>
    <child link="RF_WHEEL"/>
    <origin rpy="-1.5707963267948966 0 0" xyz="0.2159 -0.27749999999999997 -0.018500000000000003"/>
    <axis rpy="0 0 0" xyz="0 0 1"/>
    <dynamics damping="1.0" friction="0.0"/>
    <limit effort="100" velocity="10"/>
    <joint_properties damping="0.2" friction="0.2"/>
  </joint>
  <link name="RF_WHEEL">
    <collision>
      <origin rpy="0 0 0" xyz="0 0 0"/>
      <geometry>
        <cylinder length="0.0085" radius="0.145"/>
      </geometry>
    </collision>
    <visual>
      <origin rpy="-1.570796 0 1.570796" xyz="0 0 0"/>
      <geometry>
        <mesh filename="/smb_description/urdf/meshes/wheel.dae"/>
      </geometry>
    </visual>
    <inertial>
      <origin rpy="0 0 0" xyz="0 0 0"/>
      <mass value="5"/>
      <inertia ixx="0.02929166666666666" ixy="0" ixz="0" iyy="0.02929166666666666" iyz="0" izz="0.0525625"/>
    </inertial>
  </link>
  <gazebo reference="RF_WHEEL">
    <mu1 value="0.5"/>
    <mu2 value="0.5"/>
    <fdir1 value="1 0 0"/>
    <kp>10000000.0</kp>
    <kd>1.0</kd>
    <minDepth>0.005</minDepth>
    <maxVel>100.0</maxVel>
    <material>Gazebo/DarkGrey</material>
  </gazebo>
  <transmission name="RF_WHEEL_TRANS">
    <type>transmission_interface/SimpleTransmission</type>
    <joint name="RF_WHEEL_JOINT">
      <hardwareInterface>hardware_interface/VelocityJointInterface</hardwareInterface>
      <!--    <hardwareInterface>hardware_interface/EffortJointInterface</hardwareInterface>
                <hardwareInterface>hardware_interface/PositionJointInterface</hardwareInterface> -->
    </joint>
    <actuator name="RF_WHEEL_ACTUATOR">
      <hardwareInterface>hardware_interface/VelocityJointInterface</hardwareInterface>
      <!-- <hardwareInterface>hardware_interface/EffortJointInterface</hardwareInterface>
                <hardwareInterface>hardware_interface/PositionJointInterface</hardwareInterface> -->
      <mechanicalReduction>1</mechanicalReduction>
    </actuator>
  </transmission>
  <joint name="LH_WHEEL_JOINT" type="continuous">
    <parent link="base_link"/>
    <child link="LH_WHEEL"/>
    <origin rpy="-1.5707963267948966 0 0" xyz="-0.2159 0.27749999999999997 -0.018500000000000003"/>
    <axis rpy="0 0 0" xyz="0 0 1"/>
    <dynamics damping="1.0" friction="0.0"/>
    <limit effort="100" velocity="10"/>
    <joint_properties damping="0.2" friction="0.2"/>
  </joint>
  <link name="LH_WHEEL">
    <collision>
      <origin rpy="0 0 0" xyz="0 0 0"/>
      <geometry>
        <cylinder length="0.0085" radius="0.145"/>
      </geometry>
    </collision>
    <visual>
      <origin rpy="-1.570796 0 1.570796" xyz="0 0 0"/>
      <geometry>
        <mesh filename="/smb_description/urdf/meshes/wheel.dae"/>
      </geometry>
    </visual>
    <inertial>
      <origin rpy="0 0 0" xyz="0 0 0"/>
      <mass value="5"/>
      <inertia ixx="0.02929166666666666" ixy="0" ixz="0" iyy="0.02929166666666666" iyz="0" izz="0.0525625"/>
    </inertial>
  </link>
  <gazebo reference="LH_WHEEL">
    <mu1 value="0.0"/>
    <mu2 value="0.0"/>
    <fdir1 value="1 0 0"/>
    <kp>10000000.0</kp>
    <kd>1.0</kd>
    <minDepth>0.005</minDepth>
    <maxVel>100.0</maxVel>
    <material>Gazebo/DarkGrey</material>
  </gazebo>
  <transmission name="LH_WHEEL_TRANS">
    <type>transmission_interface/SimpleTransmission</type>
    <joint name="LH_WHEEL_JOINT">
      <hardwareInterface>hardware_interface/VelocityJointInterface</hardwareInterface>
      <!--    <hardwareInterface>hardware_interface/EffortJointInterface</hardwareInterface>
                <hardwareInterface>hardware_interface/PositionJointInterface</hardwareInterface> -->
    </joint>
    <actuator name="LH_WHEEL_ACTUATOR">
      <hardwareInterface>hardware_interface/VelocityJointInterface</hardwareInterface>
      <!-- <hardwareInterface>hardware_interface/EffortJointInterface</hardwareInterface>
                <hardwareInterface>hardware_interface/PositionJointInterface</hardwareInterface> -->
      <mechanicalReduction>1</mechanicalReduction>
    </actuator>
  </transmission>
  <joint name="RH_WHEEL_JOINT" type="continuous">
    <parent link="base_link"/>
    <child link="RH_WHEEL"/>
    <origin rpy="-1.5707963267948966 0 0" xyz="-0.2159 -0.27749999999999997 -0.018500000000000003"/>
    <axis rpy="0 0 0" xyz="0 0 1"/>
    <dynamics damping="1.0" friction="0.0"/>
    <limit effort="100" velocity="10"/>
    <joint_properties damping="0.2" friction="0.2"/>
  </joint>
  <link name="RH_WHEEL">
    <collision>
      <origin rpy="0 0 0" xyz="0 0 0"/>
      <geometry>
        <cylinder length="0.0085" radius="0.145"/>
      </geometry>
    </collision>
    <visual>
      <origin rpy="-1.570796 0 1.570796" xyz="0 0 0"/>
      <geometry>
        <mesh filename="/smb_description/urdf/meshes/wheel.dae"/>
      </geometry>
    </visual>
    <inertial>
      <origin rpy="0 0 0" xyz="0 0 0"/>
      <mass value="5"/>
      <inertia ixx="0.02929166666666666" ixy="0" ixz="0" iyy="0.02929166666666666" iyz="0" izz="0.0525625"/>
    </inertial>
  </link>
  <gazebo reference="RH_WHEEL">
    <mu1 value="0.2"/>
    <mu2 value="0.2"/>
    <fdir1 value="1 0 0"/>
    <kp>10000000.0</kp>
    <kd>1.0</kd>
    <minDepth>0.005</minDepth>
    <maxVel>100.0</maxVel>
    <material>Gazebo/DarkGrey</material>
  </gazebo>
  <transmission name="RH_WHEEL_TRANS">
    <type>transmission_interface/SimpleTransmission</type>
    <joint name="RH_WHEEL_JOINT">
      <hardwareInterface>hardware_interface/VelocityJointInterface</hardwareInterface>
      <!--    <hardwareInterface>hardware_interface/EffortJointInterface</hardwareInterface>
                <hardwareInterface>hardware_interface/PositionJointInterface</hardwareInterface> -->
    </joint>
    <actuator name="RH_WHEEL_ACTUATOR">
      <hardwareInterface>hardware_interface/VelocityJointInterface</hardwareInterface>
      <!-- <hardwareInterface>hardware_interface/EffortJointInterface</hardwareInterface>
                <hardwareInterface>hardware_interface/PositionJointInterface</hardwareInterface> -->
      <mechanicalReduction>1</mechanicalReduction>
    </actuator>
  </transmission>
  <gazebo>
    <plugin filename="libhector_gazebo_ros_imu.so" name="smb_imu_plugin">
      <updateRate>400</updateRate>
      <bodyName>imu_link</bodyName>
      <frameId>imu_link</frameId>
      <topicName>/imu0</topicName>
      <serviceName>/imu/calibrate</serviceName>
      <accelOffset>0.0 0.0 0.0</accelOffset>
      <accelDrift>0.0 0.0 0.0</accelDrift>
      <accelDriftFrequency>0.0 0.0 0.0</accelDriftFrequency>
      <accelGaussianNoise>0.0 0.0 0.0</accelGaussianNoise>
      <rateOffset>0.0 0.0 0.0</rateOffset>
      <rateDrift>0.0 0.0 0.0</rateDrift>
      <rateDriftFrequency>0.0 0.0 0.0</rateDriftFrequency>
      <rateGaussianNoise>0.0 0.0 0.0</rateGaussianNoise>
      <headingOffset>0.0</headingOffset>
      <headingDrift>0.0</headingDrift>
      <headingDriftFrequency>0.0</headingDriftFrequency>
      <headingGaussianNoise>0.0</headingGaussianNoise>
    </plugin>
  </gazebo>
  <!-- Imu is fixed to the base link -->
  <joint name="imu_joint" type="fixed">
    <origin rpy="0 0 0" xyz="0.2554 -0.02397 0.1795"/>
    <parent link="base_link"/>
    <child link="imu_link"/>
  </joint>
  <!-- Imu link -->
  <link name="imu_link">
    <inertial>
      <mass value="0.001"/>
      <origin rpy="0 0 0" xyz="0 0 0"/>
      <inertia ixx="0.0001" ixy="0" ixz="0" iyy="0.000001" iyz="0" izz="0.0001"/>
    </inertial>
    <visual>
      <origin rpy="0 0 0" xyz="0 0 0"/>
      <geometry>
        <!-- <box size="0.04 0.05 0.02"/> -->
        <mesh filename="/smb_description/urdf/new_payload/meshes/SMB_imu.dae"/>
      </geometry>
    </visual>
    <collision>
      <origin rpy="0 0 0" xyz="0 0 0"/>
      <geometry>
        <!-- <box size=".001 .001 .001"/> -->
        <mesh filename="/smb_description/urdf/new_payload/meshes/SMB_imu.dae"/>
      </geometry>
    </collision>
    <material name="orange">
      <color rgba="255 108 10 255"/>
    </material>
  </link>
  <link name="imu">
    <inertial>
      <mass value="0.001"/>
      <origin rpy="0 0 0" xyz="0 0 0"/>
      <inertia ixx="0.0001" ixy="0" ixz="0" iyy="0.000001" iyz="0" izz="0.0001"/>
    </inertial>
  </link>
  <joint name="imu_imu_link_joint" type="fixed">
    <origin rpy="0 0 0" xyz="0 0 0"/>
    <parent link="imu_link"/>
    <child link="imu"/>
  </joint>
  <gazebo reference="imu_link">
    <material>Gazebo/Orange</material>
  </gazebo>
  <gazebo reference="imu_joint">
    <disableFixedJointLumping>true</disableFixedJointLumping>
  </gazebo>
  <!-- <xacro:GPS base_link="${base_link_name}" simulation="${simulation}"/> -->
  <link name="mono_link">
    <inertial>
      <mass value="0.01"/>
      <!-- [kg] -->
      <inertia ixx="1e-5" ixy="0" ixz="0" iyy="1e-5" iyz="0" izz="1e-5"/>
    </inertial>
    <visual>
      <geometry>
        <box size="0.02 0.05 0.03"/>
      </geometry>
    </visual>
    <collision>
      <geometry>
        <box size="0.02 0.05 0.03"/>
      </geometry>
    </collision>
    <material name="red">
      <color rgba="255 0 10 255"/>
    </material>
  </link>
  <gazebo reference="mono_link">
    <material>Gazebo/Red</material>
  </gazebo>
  <joint name="mono_camera_joint" type="fixed">
    <origin rpy="0 0 0" xyz="0.35 -0.15 0.29"/>
    <parent link="base_link"/>
    <child link="mono_link"/>
  </joint>
  <gazebo reference="mono_camera_joint">
    <disableFixedJointLumping>true</disableFixedJointLumping>
  </gazebo>
  <gazebo reference="mono_link">
    <sensor name="mono_cam" type="camera">
      <pose>0 0 0 0 0 0</pose>
      <visualize>false</visualize>
      <update_rate>30</update_rate>
      <camera>
        <horizontal_fov>1.3962634</horizontal_fov>
        <!-- 80 deg-->
         &gt;

        <image>
          <width>640</width>
          <height>480</height>
          <format>R8G8B8</format>
        </image>
        <clip>
          <near>0.01</near>
          <far>100</far>
        </clip>
        <noise>
          <type>gaussian</type>
          <!-- Noise parameters based on published spec for Hokuyo laser
                achieving "+-30mm" accuracy at range < 10m.  A mean of 0.0m and
                stddev of 0.01m will put 99.7% of samples within 0.03m of the true
                reading. -->
          <mean>0.0</mean>
          <stddev>0.007</stddev>
        </noise>
      </camera>
      <plugin filename="libgazebo_ros_camera.so" name="gazebo_ros_camera_controller">
        <alwaysOn>true</alwaysOn>
        <updateRate>0.0</updateRate>
        <cameraName>mono_cam</cameraName>
        <imageTopicName>/mono/cam0/image_raw</imageTopicName>
        <cameraInfoTopicName>camera_info</cameraInfoTopicName>
        <frameName>mono_link</frameName>
        <hackBaseline>0.07</hackBaseline>
        <distortionK1>0.0</distortionK1>
        <distortionK2>0.0</distortionK2>
        <distortionK3>0.0</distortionK3>
        <distortionT1>0.0</distortionT1>
        <distortionT2>0.0</distortionT2>
      </plugin>
    </sensor>
  </gazebo>
  <link name="blackfly0_link">
    <inertial>
      <mass value="0.01"/>
      <!-- [kg] -->
      <inertia ixx="1e-5" ixy="0" ixz="0" iyy="1e-5" iyz="0" izz="1e-5"/>
    </inertial>
    <visual>
      <geometry>
        <mesh filename="/smb_description/urdf/new_payload/meshes/SMB_blackfly_camera.dae"/>
      </geometry>
    </visual>
    <collision>
      <geometry>
        <mesh filename="/smb_description/urdf/new_payload/meshes/SMB_blackfly_camera.dae"/>
      </geometry>
    </collision>
    <material name="red">
      <color rgba="255 0 10 255"/>
    </material>
  </link>
  <gazebo reference="blackfly0_link">
    <material>Gazebo/Red</material>
  </gazebo>
  <joint name="blackfly0_camera_joint" type="fixed">
    <!-- <origin xyz="${blackfly_origin_xyz}" rpy="${blackfly_origin_rpy}"/> -->
    <origin rpy="0 0 0" xyz="0.29082 0.04458 0.194"/>
    <parent link="base_link"/>
    <child link="blackfly0_link"/>
  </joint>
  <gazebo reference="blackfly0_camera_joint">
    <disableFixedJointLumping>true</disableFixedJointLumping>
  </gazebo>
  <link name="blackfly0_optical_link"/>
  <joint name="blackfly0_camera_optical_joint" type="fixed">
    <origin rpy="-1.57 0 -1.57" xyz="0.0066 0 0"/>
    <parent link="blackfly0_link"/>
    <child link="blackfly0_optical_link"/>
  </joint>
  <gazebo reference="blackfly0_link">
    <sensor name="blackfly0_cam" type="camera">
      <pose>0.0066 0 0 0 0 0</pose>
      <visualize>false</visualize>
      <update_rate>30</update_rate>
      <camera>
        <horizontal_fov>1.3962634</horizontal_fov>
        <!-- 80 deg-->
         &gt;

        <image>
          <width>720</width>
          <height>540</height>
          <format>R8G8B8</format>
        </image>
        <clip>
          <near>0.01</near>
          <far>100</far>
        </clip>
        <noise>
          <type>gaussian</type>
          <!-- Noise parameters based on published spec for Hokuyo laser
                achieving "+-30mm" accuracy at range < 10m.  A mean of 0.0m and
                stddev of 0.01m will put 99.7% of samples within 0.03m of the true
                reading. -->
          <mean>0.0</mean>
          <stddev>0.007</stddev>
        </noise>
      </camera>
      <plugin filename="libgazebo_ros_camera.so" name="gazebo_ros_camera_controller">
        <alwaysOn>true</alwaysOn>
        <updateRate>0.0</updateRate>
        <cameraName>blackfly0_cam</cameraName>
        <imageTopicName>/blackfly0/color/image_raw</imageTopicName>
        <cameraInfoTopicName>/blackfly0/color/camera_info</cameraInfoTopicName>
        <frameName>blackfly0_optical_link</frameName>
        <hackBaseline>0.07</hackBaseline>
        <distortionK1>0.0</distortionK1>
        <distortionK2>0.0</distortionK2>
        <distortionK3>0.0</distortionK3>
        <distortionT1>0.0</distortionT1>
        <distortionT2>0.0</distortionT2>
      </plugin>
    </sensor>
  </gazebo>
  <link name="blackfly1_link">
    <inertial>
      <mass value="0.01"/>
      <!-- [kg] -->
      <inertia ixx="1e-5" ixy="0" ixz="0" iyy="1e-5" iyz="0" izz="1e-5"/>
    </inertial>
    <visual>
      <geometry>
        <mesh filename="/smb_description/urdf/new_payload/meshes/SMB_blackfly_camera.dae"/>
      </geometry>
    </visual>
    <collision>
      <geometry>
        <mesh filename="/smb_description/urdf/new_payload/meshes/SMB_blackfly_camera.dae"/>
      </geometry>
    </collision>
    <material name="red">
      <color rgba="255 0 10 255"/>
    </material>
  </link>
  <gazebo reference="blackfly1_link">
    <material>Gazebo/Red</material>
  </gazebo>
  <joint name="blackfly1_camera_joint" type="fixed">
    <!-- <origin xyz="${blackfly_origin_xyz}" rpy="${blackfly_origin_rpy}"/> -->
    <origin rpy="0 0 0" xyz="0.29082 -0.04542 0.194"/>
    <parent link="base_link"/>
    <child link="blackfly1_link"/>
  </joint>
  <gazebo reference="blackfly1_camera_joint">
    <disableFixedJointLumping>true</disableFixedJointLumping>
  </gazebo>
  <link name="blackfly1_optical_link"/>
  <joint name="blackfly1_camera_optical_joint" type="fixed">
    <origin rpy="-1.57 0 -1.57" xyz="0.0066 0 0"/>
    <parent link="blackfly1_link"/>
    <child link="blackfly1_optical_link"/>
  </joint>
  <gazebo reference="blackfly1_link">
    <sensor name="blackfly1_cam" type="camera">
      <pose>0.0066 0 0 0 0 0</pose>
      <visualize>false</visualize>
      <update_rate>30</update_rate>
      <camera>
        <horizontal_fov>1.3962634</horizontal_fov>
        <!-- 80 deg-->
         &gt;

        <image>
          <width>720</width>
          <height>540</height>
          <format>R8G8B8</format>
        </image>
        <clip>
          <near>0.01</near>
          <far>100</far>
        </clip>
        <noise>
          <type>gaussian</type>
          <!-- Noise parameters based on published spec for Hokuyo laser
                achieving "+-30mm" accuracy at range < 10m.  A mean of 0.0m and
                stddev of 0.01m will put 99.7% of samples within 0.03m of the true
                reading. -->
          <mean>0.0</mean>
          <stddev>0.007</stddev>
        </noise>
      </camera>
      <plugin filename="libgazebo_ros_camera.so" name="gazebo_ros_camera_controller">
        <alwaysOn>true</alwaysOn>
        <updateRate>0.0</updateRate>
        <cameraName>blackfly1_cam</cameraName>
        <imageTopicName>/blackfly1/color/image_raw</imageTopicName>
        <cameraInfoTopicName>/blackfly1/color/camera_info</cameraInfoTopicName>
        <frameName>blackfly1_optical_link</frameName>
        <hackBaseline>0.07</hackBaseline>
        <distortionK1>0.0</distortionK1>
        <distortionK2>0.0</distortionK2>
        <distortionK3>0.0</distortionK3>
        <distortionT1>0.0</distortionT1>
        <distortionT2>0.0</distortionT2>
      </plugin>
    </sensor>
  </gazebo>
  <link name="blackfly_left_link">
    <inertial>
      <mass value="0.01"/>
      <!-- [kg] -->
      <inertia ixx="1e-5" ixy="0" ixz="0" iyy="1e-5" iyz="0" izz="1e-5"/>
    </inertial>
    <visual>
      <geometry>
        <mesh filename="/smb_description/urdf/new_payload/meshes/SMB_blackfly_camera.dae"/>
      </geometry>
    </visual>
    <collision>
      <geometry>
        <mesh filename="/smb_description/urdf/new_payload/meshes/SMB_blackfly_camera.dae"/>
      </geometry>
    </collision>
    <material name="red">
      <color rgba="255 0 10 255"/>
    </material>
  </link>
  <gazebo reference="blackfly_left_link">
    <material>Gazebo/Red</material>
  </gazebo>
  <link name="blackfly_right_link">
    <inertial>
      <mass value="0.01"/>
      <!-- [kg] -->
      <inertia ixx="1e-5" ixy="0" ixz="0" iyy="1e-5" iyz="0" izz="1e-5"/>
    </inertial>
    <visual>
      <geometry>
        <mesh filename="/smb_description/urdf/new_payload/meshes/SMB_blackfly_camera.dae"/>
      </geometry>
    </visual>
    <collision>
      <geometry>
        <mesh filename="/smb_description/urdf/new_payload/meshes/SMB_blackfly_camera.dae"/>
      </geometry>
    </collision>
    <material name="red">
      <color rgba="255 0 10 255"/>
    </material>
  </link>
  <gazebo reference="blackfly_right_link">
    <material>Gazebo/Red</material>
  </gazebo>
  <joint name="blackfly_left_camera_joint" type="fixed">
    <origin rpy="0 0 0" xyz="0.29082 0.04458 0.194"/>
    <parent link="base_link"/>
    <child link="blackfly_left_link"/>
  </joint>
  <gazebo reference="blackfly_left_camera_joint">
    <disableFixedJointLumping>true</disableFixedJointLumping>
  </gazebo>
  <joint name="blackfly_right_camera_joint" type="fixed">
    <origin rpy="0 0 0" xyz="0.29082 -0.04542 0.194"/>
    <parent link="base_link"/>
    <child link="blackfly_right_link"/>
  </joint>
  <gazebo reference="blackfly_right_camera_joint">
    <disableFixedJointLumping>true</disableFixedJointLumping>
  </gazebo>
  <link name="blackfly_left_optical_link"/>
  <link name="blackfly_right_optical_link"/>
  <joint name="blackfly_left_camera_optical_joint" type="fixed">
    <origin rpy="-1.57 0 -1.57" xyz="0.0066 0 0"/>
    <parent link="blackfly_left_link"/>
    <child link="blackfly_left_optical_link"/>
  </joint>
  <joint name="blackfly_right_camera_optical_joint" type="fixed">
    <origin rpy="-1.57 0 -1.57" xyz="0.0066 0 0"/>
    <parent link="blackfly_right_link"/>
    <child link="blackfly_right_optical_link"/>
  </joint>
  <gazebo reference="blackfly_left_link">
    <sensor name="blackfly_stereo_cam" type="multicamera">
      <visualize>false</visualize>
      <update_rate>30</update_rate>
      <camera name="left">
        <pose>0.0066 0 0 0 0 0</pose>
        <horizontal_fov>1.3962634</horizontal_fov>
        <!-- 80 deg-->
         &gt;

        <image>
          <width>720</width>
          <height>540</height>
          <format>R8G8B8</format>
        </image>
        <clip>
          <near>0.01</near>
          <far>300</far>
        </clip>
        <noise>
          <type>gaussian</type>
          <!-- Noise parameters based on published spec for Hokuyo laser
                achieving "+-30mm" accuracy at range < 10m.  A mean of 0.0m and
                stddev of 0.01m will put 99.7% of samples within 0.03m of the true
                reading. -->
          <mean>0.0</mean>
          <stddev>0.007</stddev>
        </noise>
      </camera>
      <camera name="right">
        <pose>0.0066 -0.09 0 0 0 0</pose>
        <horizontal_fov>1.3962634</horizontal_fov>
        <!-- 80 deg-->
         &gt;

        <image>
          <width>720</width>
          <height>540</height>
          <format>R8G8B8</format>
        </image>
        <clip>
          <near>0.01</near>
          <far>300</far>
        </clip>
        <noise>
          <type>gaussian</type>
          <!-- Noise parameters based on published spec for Hokuyo laser
                achieving "+-30mm" accuracy at range < 10m.  A mean of 0.0m and
                stddev of 0.01m will put 99.7% of samples within 0.03m of the true
                reading. -->
          <mean>0.0</mean>
          <stddev>0.007</stddev>
        </noise>
      </camera>
      <plugin filename="libgazebo_ros_multicamera.so" name="stereo_camera_controller">
        <alwaysOn>true</alwaysOn>
        <updateRate>0.0</updateRate>
        <cameraName>blackfly_stereo_cam</cameraName>
        <imageTopicName>image_raw</imageTopicName>
        <cameraInfoTopicName>camera_info</cameraInfoTopicName>
        <frameName>blackfly_left_optical_link</frameName>
        <hackBaseline>0.09</hackBaseline>
        <distortionK1>0.0</distortionK1>
        <distortionK2>0.0</distortionK2>
        <distortionK3>0.0</distortionK3>
        <distortionT1>0.0</distortionT1>
        <distortionT2>0.0</distortionT2>
      </plugin>
    </sensor>
  </gazebo>
  <link name="lidar_mount_link">
    <visual>
      <geometry>
        <mesh filename="/smb_description/urdf/new_payload/meshes/SMB_lidar_mount.dae"/>
      </geometry>
    </visual>
    <inertial>
      <origin rpy="0 0 0" xyz="0 0 0"/>
      <mass value="0.5"/>
      <inertia ixx="0.0007291666666666667" ixy="0" ixz="0" iyy="0.0007291666666666667" iyz="0" izz="0.0006250000000000001"/>
      <!-- you need some inertial otherwise the link start spinning in gazebo -->
    </inertial>
  </link>
  <gazebo reference="lidar_mount_link">
    <material>Gazebo/Grey</material>
  </gazebo>
  <joint name="lidar_mount_joint" type="fixed">
    <origin rpy="0 0 0" xyz="0.245 0 0.3265"/>
    <parent link="base_link"/>
    <child link="lidar_mount_link"/>
  </joint>
  <gazebo reference="lidar_mount_joint">
    <disableFixedJointLumping>true</disableFixedJointLumping>
  </gazebo>
  <joint name="rslidar_base_mount_joint" type="fixed">
    <origin rpy="0 0 1.5707963267948966" xyz="0 0 0.14"/>
    <parent link="lidar_mount_link"/>
    <child link="rslidar_base_link"/>
  </joint>
  <link name="rslidar_base_link">
    <inertial>
      <mass value="0.87"/>
      <origin xyz="0 0 0"/>
      <inertia ixx="0.001094695" ixy="0" ixz="0" iyy="0.001094695" iyz="0" izz="0.001245079"/>
    </inertial>
    <visual>
      <origin rpy="-1.5707 0 0" xyz="0 0 0"/>
      <geometry>
        <mesh filename="/robosense_description/meshes/robosense_16.dae"/>
      </geometry>
    </visual>
    <collision>
      <origin rpy="0 0 0" xyz="0 0 0"/>
      <geometry>
        <cylinder length="0.0817" radius="0.0535"/>
      </geometry>
    </collision>
  </link>
  <joint name="rslidar_base_scan_joint" type="fixed">
    <origin rpy="0 0 0" xyz="0 0 0.039"/>
    <parent link="rslidar_base_link"/>
    <child link="rslidar"/>
  </joint>
  <link name="rslidar">
    <inertial>
      <mass value="0.01"/>
      <origin xyz="0 0 0"/>
      <inertia ixx="1e-7" ixy="0" ixz="0" iyy="1e-7" iyz="0" izz="1e-7"/>
    </inertial>
  </link>
  <!-- Gazebo requires the robosense_gazebo_plugins package -->
  <gazebo reference="rslidar">
    <sensor name="rslidar-RS16" type="ray">
      <pose>0 0 0 0 0 0</pose>
      <visualize>false</visualize>
      <update_rate>10</update_rate>
      <ray>
        <scan>
          <horizontal>
            <samples>440</samples>
            <resolution>1</resolution>
            <min_angle>-3.141592653589793</min_angle>
            <max_angle>3.141592653589793</max_angle>
          </horizontal>
          <vertical>
            <samples>16</samples>
            <resolution>1</resolution>
            <min_angle>-0.2617993877991494</min_angle>
            <max_angle> 0.2617993877991494</max_angle>
          </vertical>
        </scan>
        <range>
          <min>0.4</min>
          <max>151.0</max>
          <resolution>0.001</resolution>
        </range>
        <noise>
          <type>gaussian</type>
          <mean>0.0</mean>
          <stddev>0.0</stddev>
        </noise>
      </ray>
      <plugin filename="libgazebo_ros_robosense_laser.so" name="gazebo_ros_laser_controller">
        <topicName>/rslidar_points</topicName>
        <frameName>rslidar</frameName>
        <min_range>0.4</min_range>
        <max_range>150.0</max_range>
        <gaussianNoise>0.008</gaussianNoise>
      </plugin>
    </sensor>
  </gazebo>
  <gazebo reference="rslidar_base_mount_joint">
    <preserveFixedJoint>true</preserveFixedJoint>
  </gazebo>
  <gazebo reference="rslidar_base_scan_joint">
    <preserveFixedJoint>true</preserveFixedJoint>
  </gazebo>
  <gazebo>
    <plugin filename="libodometry_source_plugin.so" name="smb_odometry_plugin">
      <robotNamespace>smb</robotNamespace>
      <bodyName>rslidar</bodyName>
      <topicName>/rslidar_ground_truth</topicName>
      <odomFrame>map</odomFrame>
      <childOdomFrame>lidar</childOdomFrame>
      <publishTf>False</publishTf>
      <xyzOffset>0 0 0</xyzOffset>
      <rpyOffset>0 0 0</rpyOffset>
      <gaussianNoise>0</gaussianNoise>
      <updateRate>20</updateRate>
      <maxLinearSpeedBeforeSettle>0.01</maxLinearSpeedBeforeSettle>
      <maxAngularSpeedBeforeSettle>0.1</maxAngularSpeedBeforeSettle>
    </plugin>
  </gazebo>
  <link name="realsense_t265">
    <inertial>
      <mass value="0.001"/>
      <origin rpy="0 0 0" xyz="0 0 0"/>
      <inertia ixx="0.0001" ixy="0" ixz="0" iyy="0.000001" iyz="0" izz="0.0001"/>
    </inertial>
    <collision>
      <origin rpy="0 0 0" xyz="0 0 0"/>
      <geometry>
        <box size="0.013 0.108 0.025"/>
      </geometry>
    </collision>
    <visual>
      <origin rpy="0 0 0" xyz="0 0 0"/>
      <geometry>
        <box size="0.013 0.108 0.025"/>
      </geometry>
      <material name="black"/>
    </visual>
  </link>
  <gazebo reference="realsense_t265">
    <material>Gazebo/Black</material>
  </gazebo>
  <joint name="realsense_t265_joint" type="fixed">
    <parent link="imu_link"/>
    <child link="realsense_t265"/>
    <!-- <origin xyz="-${chassisLength/2.0+realsense_t265_width} 0.0 ${chassisHeight*0.5+realsense_t265_height*0.5}" rpy="0 0 ${PI}" /> -->
    <!-- Manually calibrated sensor orientation  -->
    <origin rpy="0 0 0" xyz="0.0537 0.0321 0.172"/>
  </joint>
  <joint name="camera_pose_frame_joint" type="fixed">
    <parent link="realsense_t265"/>
    <child link="camera_pose_frame"/>
    <origin rpy="0 0 0" xyz="0 0 0"/>
  </joint>
  <link name="camera_pose_frame"/>
  <link name="realsense_t265_odom_frame"/>
  <joint name="realsense_t265_odom_joint" type="fixed">
    <parent link="realsense_t265"/>
    <child link="realsense_t265_odom_frame"/>
    <origin rpy="1.5707963267948966 0 -1.5707963267948966" xyz="0 0.0091 0 "/>
  </joint>
  <link name="camera_imu_optical_frame"/>
  <joint name="realsense_t265_imu_joint" type="fixed">
    <parent link="realsense_t265_odom_frame"/>
    <child link="camera_imu_optical_frame"/>
    <origin rpy="0 3.141592653589793 0" xyz="0 0 0 "/>
  </joint>
  <gazebo>
    <plugin filename="libodometry_source_plugin.so" name="smb_odometry_plugin">
      <robotNamespace>smb</robotNamespace>
      <bodyName>realsense_t265</bodyName>
      <topicName>/camera/odom/sample</topicName>
      <odomFrame>camera_odom_frame</odomFrame>
      <childOdomFrame>camera_pose_frame</childOdomFrame>
      <publishTf>True</publishTf>
      <xyzOffset>0 0 0</xyzOffset>
      <rpyOffset>0 0 0</rpyOffset>
      <gaussianNoise>0</gaussianNoise>
      <updateRate>200</updateRate>
      <maxLinearSpeedBeforeSettle>0.01</maxLinearSpeedBeforeSettle>
      <maxAngularSpeedBeforeSettle>0.05</maxAngularSpeedBeforeSettle>
    </plugin>
  </gazebo>
  <gazebo reference="realsense_t265_joint">
    <disableFixedJointLumping>true</disableFixedJointLumping>
  </gazebo>
  <!-- panda arm  -->
  <!--xacro:if value="${sim}"-->
  <!-- Up until franka-description 0.9.x -->
  <!--xacro:include filename="$(find franka_description)/robots/panda_gazebo.xacro"/-->
  <!--/xacro:if>
    <xacro:unless value="${sim}">
        <xacro:include filename="$(find franka_description)/robots/panda_arm.xacro"/>
    </xacro:unless-->
  <!-- Up until franka-description 0.9.x -->
  <!--xacro:panda_arm connected_to="${connected_to}" rpy="${rpy}" xyz="${xyz}"/-->
  <joint name="panda_joint_arm_mount_link" type="fixed">
    <parent link="arm_mount_link"/>
    <child link="panda_link0"/>
    <origin rpy="0 0 0" xyz="0 0 0"/>
  </joint>
  <!-- sub-link defining detailed meshes for collision with environment -->
  <link name="panda_link0">
    <visual>
      <geometry>
        <mesh filename="/franka_description/meshes/visual/link0.dae"/>
      </geometry>
    </visual>
    <collision>
      <geometry>
        <mesh filename="/franka_description/meshes/collision/link0.stl"/>
      </geometry>
    </collision>
    <inertial>
      <origin rpy="0 0 0" xyz="-0.041018 -0.00014 0.049974"/>
      <mass value="0.629769"/>
      <inertia ixx="0.00315" ixy="8.2904e-07" ixz="0.00015" iyy="0.00388" iyz="8.2299e-06" izz="0.004285"/>
    </inertial>
  </link>
  <!-- sub-link defining coarse geometries of real robot's internal self-collision -->
  <link name="panda_link0_sc">
  </link>
  <!-- fixed joint between both sub-links -->
  <joint name="panda_link0_sc_joint" type="fixed">
    <origin rpy="0 0 0"/>
    <parent link="panda_link0"/>
    <child link="panda_link0_sc"/>
  </joint>
  <!-- sub-link defining detailed meshes for collision with environment -->
  <link name="panda_link1">
    <visual>
      <geometry>
        <mesh filename="/franka_description/meshes/visual/link1.dae"/>
      </geometry>
    </visual>
    <collision>
      <geometry>
        <mesh filename="/franka_description/meshes/collision/link1.stl"/>
      </geometry>
    </collision>
    <inertial>
      <origin rpy="0 0 0" xyz="0.003875 0.002081 -0.04762"/>
      <mass value="4.970684"/>
      <inertia ixx="0.70337" ixy="-0.000139" ixz="0.006772" iyy="0.70661" iyz="0.019169" izz="0.009117"/>
    </inertial>
  </link>
  <!-- sub-link defining coarse geometries of real robot's internal self-collision -->
  <link name="panda_link1_sc">
  </link>
  <!-- fixed joint between both sub-links -->
  <joint name="panda_link1_sc_joint" type="fixed">
    <origin rpy="0 0 0"/>
    <parent link="panda_link1"/>
    <child link="panda_link1_sc"/>
  </joint>
  <joint name="panda_joint1" type="revolute">
    <origin rpy="0 0 0" xyz="0 0 0.333"/>
    <parent link="panda_link0"/>
    <child link="panda_link1"/>
    <axis xyz="0 0 1"/>
    <limit effort="87.0" lower="-2.8973" upper="2.8973" velocity="2.175"/>
    <safety_controller k_position="100.0" k_velocity="40.0" soft_lower_limit="-2.8973" soft_upper_limit="2.8973"/>
    <dynamics D="1" K="7000" damping="0.003" friction="0.0" mu_coulomb="0" mu_viscous="16"/>
  </joint>
  <!-- sub-link defining detailed meshes for collision with environment -->
  <link name="panda_link2">
    <visual>
      <geometry>
        <mesh filename="/franka_description/meshes/visual/link2.dae"/>
      </geometry>
    </visual>
    <collision>
      <geometry>
        <mesh filename="/franka_description/meshes/collision/link2.stl"/>
      </geometry>
    </collision>
    <inertial>
      <origin rpy="0 0 0" xyz="-0.003141 -0.02872  0.003495"/>
      <mass value="0.646926"/>
      <inertia ixx="0.007962" ixy="-0.003925" ixz="0.010254" iyy="0.02811" iyz="0.000704" izz="0.025995"/>
    </inertial>
  </link>
  <!-- sub-link defining coarse geometries of real robot's internal self-collision -->
  <link name="panda_link2_sc">
  </link>
  <!-- fixed joint between both sub-links -->
  <joint name="panda_link2_sc_joint" type="fixed">
    <origin rpy="0 0 0"/>
    <parent link="panda_link2"/>
    <child link="panda_link2_sc"/>
  </joint>
  <joint name="panda_joint2" type="revolute">
    <origin rpy="-1.5707963267948966 0 0" xyz="0 0 0"/>
    <parent link="panda_link1"/>
    <child link="panda_link2"/>
    <axis xyz="0 0 1"/>
    <limit effort="87.0" lower="-1.7628" upper="1.7628" velocity="2.175"/>
    <safety_controller k_position="100.0" k_velocity="40.0" soft_lower_limit="-1.7628" soft_upper_limit="1.7628"/>
    <dynamics D="1" K="7000" damping="0.003" friction="0.0" mu_coulomb="0" mu_viscous="16"/>
  </joint>
  <!-- sub-link defining detailed meshes for collision with environment -->
  <link name="panda_link3">
    <visual>
      <geometry>
        <mesh filename="/franka_description/meshes/visual/link3.dae"/>
      </geometry>
    </visual>
    <collision>
      <geometry>
        <mesh filename="/franka_description/meshes/collision/link3.stl"/>
      </geometry>
    </collision>
    <inertial>
      <origin rpy="0 0 0" xyz="2.7518e-02 3.9252e-02 -6.6502e-02"/>
      <mass value="3.228604"/>
      <inertia ixx="0.037242" ixy="-0.004761" ixz="-0.011396" iyy="0.036155" iyz="-0.012805" izz="0.01083"/>
    </inertial>
  </link>
  <!-- sub-link defining coarse geometries of real robot's internal self-collision -->
  <link name="panda_link3_sc">
  </link>
  <!-- fixed joint between both sub-links -->
  <joint name="panda_link3_sc_joint" type="fixed">
    <origin rpy="0 0 0"/>
    <parent link="panda_link3"/>
    <child link="panda_link3_sc"/>
  </joint>
  <joint name="panda_joint3" type="revolute">
    <origin rpy="1.5707963267948966 0 0" xyz="0 -0.316 0"/>
    <parent link="panda_link2"/>
    <child link="panda_link3"/>
    <axis xyz="0 0 1"/>
    <limit effort="87.0" lower="-2.8973" upper="2.8973" velocity="2.175"/>
    <safety_controller k_position="100.0" k_velocity="40.0" soft_lower_limit="-2.8973" soft_upper_limit="2.8973"/>
    <dynamics D="1" K="7000" damping="0.003" friction="0.0" mu_coulomb="0" mu_viscous="16"/>
  </joint>
  <!-- sub-link defining detailed meshes for collision with environment -->
  <link name="panda_link4">
    <visual>
      <geometry>
        <mesh filename="/franka_description/meshes/visual/link4.dae"/>
      </geometry>
    </visual>
    <collision>
      <geometry>
        <mesh filename="/franka_description/meshes/collision/link4.stl"/>
      </geometry>
    </collision>
    <inertial>
      <origin rpy="0 0 0" xyz="-5.317e-02 1.04419e-01 2.7454e-02"/>
      <mass value="3.587895"/>
      <inertia ixx="0.025853" ixy="0.007796" ixz="-0.001332" iyy="0.019552" iyz="0.008641" izz="0.028323"/>
    </inertial>
  </link>
  <!-- sub-link defining coarse geometries of real robot's internal self-collision -->
  <link name="panda_link4_sc">
  </link>
  <!-- fixed joint between both sub-links -->
  <joint name="panda_link4_sc_joint" type="fixed">
    <origin rpy="0 0 0"/>
    <parent link="panda_link4"/>
    <child link="panda_link4_sc"/>
  </joint>
  <joint name="panda_joint4" type="revolute">
    <origin rpy="1.5707963267948966 0 0" xyz="0.0825 0 0"/>
    <parent link="panda_link3"/>
    <child link="panda_link4"/>
    <axis xyz="0 0 1"/>
    <limit effort="87.0" lower="-3.0718" upper="-0.0698" velocity="2.175"/>
    <safety_controller k_position="100.0" k_velocity="40.0" soft_lower_limit="-3.0718" soft_upper_limit="-0.0698"/>
    <dynamics D="1" K="7000" damping="0.003" friction="0.0" mu_coulomb="0" mu_viscous="16"/>
  </joint>
  <!-- sub-link defining detailed meshes for collision with environment -->
  <link name="panda_link5">
    <visual>
      <geometry>
        <mesh filename="/franka_description/meshes/visual/link5.dae"/>
      </geometry>
    </visual>
    <collision>
      <geometry>
        <mesh filename="/franka_description/meshes/collision/link5.stl"/>
      </geometry>
    </collision>
    <inertial>
      <origin rpy="0 0 0" xyz="-1.1953e-02 4.1065e-02 -3.8437e-02"/>
      <mass value="1.225946"/>
      <inertia ixx="0.035549" ixy="-0.002117" ixz="-0.004037" iyy="0.029474" iyz="0.000229" izz="0.008627"/>
    </inertial>
  </link>
  <!-- sub-link defining coarse geometries of real robot's internal self-collision -->
  <link name="panda_link5_sc">
  </link>
  <!-- fixed joint between both sub-links -->
  <joint name="panda_link5_sc_joint" type="fixed">
    <origin rpy="0 0 0"/>
    <parent link="panda_link5"/>
    <child link="panda_link5_sc"/>
  </joint>
  <joint name="panda_joint5" type="revolute">
    <origin rpy="-1.5707963267948966 0 0" xyz="-0.0825 0.384 0"/>
    <parent link="panda_link4"/>
    <child link="panda_link5"/>
    <axis xyz="0 0 1"/>
    <limit effort="12.0" lower="-2.8973" upper="2.8973" velocity="2.61"/>
    <safety_controller k_position="100.0" k_velocity="40.0" soft_lower_limit="-2.8973" soft_upper_limit="2.8973"/>
    <dynamics D="1" K="7000" damping="0.003" friction="0.0" mu_coulomb="0" mu_viscous="16"/>
  </joint>
  <!-- sub-link defining detailed meshes for collision with environment -->
  <link name="panda_link6">
    <visual>
      <geometry>
        <mesh filename="/franka_description/meshes/visual/link6.dae"/>
      </geometry>
    </visual>
    <collision>
      <geometry>
        <mesh filename="/franka_description/meshes/collision/link6.stl"/>
      </geometry>
    </collision>
    <inertial>
      <origin rpy="0 0 0" xyz="6.0149e-02 -1.4117e-02 -1.0517e-02"/>
      <mass value="1.666555"/>
      <inertia ixx="0.001964" ixy="0.000109" ixz="-0.001158" iyy="0.004354" iyz="0.000341" izz="0.005433"/>
    </inertial>
  </link>
  <!-- sub-link defining coarse geometries of real robot's internal self-collision -->
  <link name="panda_link6_sc">
  </link>
  <!-- fixed joint between both sub-links -->
  <joint name="panda_link6_sc_joint" type="fixed">
    <origin rpy="0 0 0"/>
    <parent link="panda_link6"/>
    <child link="panda_link6_sc"/>
  </joint>
  <joint name="panda_joint6" type="revolute">
    <origin rpy="1.5707963267948966 0 0" xyz="0 0 0"/>
    <parent link="panda_link5"/>
    <child link="panda_link6"/>
    <axis xyz="0 0 1"/>
    <limit effort="12.0" lower="-0.0175" upper="3.7525" velocity="2.61"/>
    <safety_controller k_position="100.0" k_velocity="40.0" soft_lower_limit="-0.0175" soft_upper_limit="3.7525"/>
    <dynamics D="1" K="7000" damping="0.003" friction="0.0" mu_coulomb="0" mu_viscous="16"/>
  </joint>
  <!-- sub-link defining detailed meshes for collision with environment -->
  <link name="panda_link7">
    <visual>
      <geometry>
        <mesh filename="/franka_description/meshes/visual/link7.dae"/>
      </geometry>
    </visual>
    <collision>
      <geometry>
        <mesh filename="/franka_description/meshes/collision/link7.stl"/>
      </geometry>
    </collision>
    <inertial>
      <origin rpy="0 0 0" xyz="1.0517e-02 -4.252e-03 6.1597e-02"/>
      <mass value="0.735522"/>
      <inertia ixx="0.012516" ixy="-0.000428" ixz="-0.001196" iyy="0.010027" iyz="-0.000741" izz="0.004815"/>
    </inertial>
  </link>
  <!-- sub-link defining coarse geometries of real robot's internal self-collision -->
  <link name="panda_link7_sc">
  </link>
  <!-- fixed joint between both sub-links -->
  <joint name="panda_link7_sc_joint" type="fixed">
    <origin rpy="0 0 0.7853981633974483"/>
    <parent link="panda_link7"/>
    <child link="panda_link7_sc"/>
  </joint>
  <joint name="panda_joint7" type="revolute">
    <origin rpy="1.5707963267948966 0 0" xyz="0.088 0 0"/>
    <parent link="panda_link6"/>
    <child link="panda_link7"/>
    <axis xyz="0 0 1"/>
    <limit effort="12.0" lower="-2.8973" upper="2.8973" velocity="2.61"/>
    <safety_controller k_position="100.0" k_velocity="40.0" soft_lower_limit="-2.8973" soft_upper_limit="2.8973"/>
    <dynamics D="1" K="7000" damping="0.003" friction="0.0" mu_coulomb="0" mu_viscous="16"/>
  </joint>
  <link name="panda_link8"/>
  <joint name="panda_joint8" type="fixed">
    <origin rpy="0 0 0" xyz="0 0 0.107"/>
    <parent link="panda_link7"/>
    <child link="panda_link8"/>
  </joint>
  <link name="tool_frame"/>
  <joint name="tool_frame_joint" type="fixed">
    <parent link="panda_link8"/>
    <child link="tool_frame"/>
    <origin rpy="0 0 -0.785398163397" xyz="0 0 0.12"/>
  </joint>
  <joint name="panda_hand_joint" type="fixed">
    <parent link="panda_link8"/>
    <child link="panda_hand"/>
    <origin rpy="0 0 -0.7853981633974483" xyz="0 0 0"/>
  </joint>
  <link name="panda_hand">
    <visual>
      <geometry>
        <mesh filename="/franka_description/meshes/visual/hand.dae"/>
      </geometry>
    </visual>
    <collision>
      <origin rpy="0 1.5707963267948966 1.5707963267948966" xyz="0 0 0.04"/>
      <geometry>
        <cylinder length="0.1" radius="0.04"/>
      </geometry>
    </collision>
    <collision>
      <origin rpy="0 0 0" xyz="0 -0.05 0.04"/>
      <geometry>
        <sphere radius="0.04"/>
      </geometry>
    </collision>
    <collision>
      <origin rpy="0 0 0" xyz="0 0.05 0.04"/>
      <geometry>
        <sphere radius="0.04"/>
      </geometry>
    </collision>
    <!-- <collision>
        <origin xyz="0 0 0.1" rpy="0 ${pi/2} ${pi/2}"/>
        <geometry>
          <cylinder radius="${0.02+safety_distance}" length="0.1" />
        </geometry>
      </collision>
      <collision>
        <origin xyz="0 -0.05 0.1" rpy="0 0 0"/>
        <geometry>
          <sphere radius="${0.02+safety_distance}"  />
        </geometry>
      </collision>
      <collision>
        <origin xyz="0 0.05 0.1" rpy="0 0 0"/>
        <geometry>
          <sphere radius="${0.02+safety_distance}"  />
        </geometry>
      </collision> -->
    <inertial>
      <origin rpy="0 0 0" xyz="0 0 0"/>
      <mass value="0.68"/>
      <inertia ixx="0.1" ixy="0.0" ixz="0.0" iyy="0.1" iyz="0.0" izz="0.1"/>
    </inertial>
  </link>
  <link name="panda_leftfinger">
    <visual>
      <geometry>
        <mesh filename="/moma_description/meshes/panda_cylinder_finger_flange.dae"/>
      </geometry>
    </visual>
    <collision>
      <geometry>
        <mesh filename="/moma_description/meshes/panda_cylinder_finger_flange.dae"/>
      </geometry>
    </collision>
    <inertial>
      <origin rpy="0 0 0" xyz="0 0 0"/>
      <mass value="0.68"/>
      <inertia ixx="0.1" ixy="0.0" ixz="0.0" iyy="0.1" iyz="0.0" izz="0.1"/>
    </inertial>
  </link>
  <link name="panda_rightfinger">
    <visual>
      <origin rpy="0 0 3.141592653589793" xyz="0 0 0"/>
      <geometry>
        <mesh filename="/moma_description/meshes/panda_cylinder_finger_flange.dae"/>
      </geometry>
    </visual>
    <collision>
      <origin rpy="0 0 3.141592653589793" xyz="0 0 0"/>
      <geometry>
        <mesh filename="/moma_description/meshes/panda_cylinder_finger_flange.dae"/>
      </geometry>
    </collision>
    <inertial>
      <origin rpy="0 0 0" xyz="0 0 0"/>
      <mass value="0.68"/>
      <inertia ixx="0.1" ixy="0.0" ixz="0.0" iyy="0.1" iyz="0.0" izz="0.1"/>
    </inertial>
  </link>
  <joint name="panda_finger_joint1" type="prismatic">
    <parent link="panda_hand"/>
    <child link="panda_leftfinger"/>
    <origin rpy="0 0 0" xyz="0 0 0.0584"/>
    <axis xyz="0 1 0"/>
    <limit effort="20" lower="0.0" upper="0.04" velocity="0.2"/>
  </joint>
  <joint name="panda_finger_joint2" type="prismatic">
    <parent link="panda_hand"/>
    <child link="panda_rightfinger"/>
    <origin rpy="0 0 0" xyz="0 0 0.0584"/>
    <axis xyz="0 -1 0"/>
    <limit effort="20" lower="0.0" upper="0.04" velocity="0.2"/>
    <mimic joint="panda_finger_joint1"/>
  </joint>
  <gazebo reference="panda_hand"/>
  <gazebo reference="panda_leftfinger"/>
  <gazebo reference="panda_rightfinger"/>
  <transmission name="panda_finger_joint1_trans">
    <type>transmission_interface/SimpleTransmission</type>
    <joint name="panda_finger_joint1">
      <hardwareInterface>hardware_interface/PositionJointInterface</hardwareInterface>
    </joint>
    <actuator name="panda_finger_joint1_motor">
      <mechanicalReduction>1</mechanicalReduction>
    </actuator>
  </transmission>
  <!-- Don't need this since the second joint is to be mimicked -->
  <!-- <transmission name="${arm_id}_finger_joint2_trans">
      <type>transmission_interface/SimpleTransmission</type>
      <joint name="${arm_id}_finger_joint2">
        <hardwareInterface>hardware_interface/PositionJointInterface</hardwareInterface>
      </joint>
      <actuator name="${arm_id}_finger_joint2_motor">
        <mechanicalReduction>1</mechanicalReduction>
      </actuator>
    </transmission> -->
  <!-- gazebo plugin to mimic finger joints -->
  <gazebo>
    <plugin filename="libroboticsgroup_gazebo_mimic_joint_plugin.so" name="panda_hand_mimic_joint_plugin">
      <joint>panda_finger_joint1</joint>
      <mimicJoint>panda_finger_joint2</mimicJoint>
      <hasPID/>
      <multiplier>2.0</multiplier>
    </plugin>
  </gazebo>
  <!-- end effector frame for MoveIt -->
  <link name="panda_default_ee"/>
  <joint name="joint_link8_default_ee" type="fixed">
    <parent link="panda_link8"/>
    <child link="panda_default_ee"/>
    <origin rpy="0.0 0.0 -0.785" xyz="0.0 0.0 0.103"/>
  </joint>
  <!-- end effector as for the real hardware -->
  <link name="panda_EE"/>
  <joint name="joint_link8_panda_EE" type="fixed">
    <parent link="panda_link8"/>
    <child link="panda_EE"/>
    <origin rpy="0.0 0.0 -0.785" xyz="0.0 0.0 0.103"/>
  </joint>
  <material name="aluminum">
    <color rgba="0.5 0.5 0.5 1"/>
  </material>
  <material name="plastic">
    <color rgba="0.1 0.1 0.1 1"/>
  </material>
  <!-- !!! There is some rounding error happening inside gazebo. This set of values is the one that do not cause
      inconsistencies and gazebo to complain. Change them at your own risk. -->
  <gazebo reference="hand_eye_link">
    <sensor name="hand_eye" type="depth">
      <always_on>true</always_on>
      <update_rate>30</update_rate>
      <camera>
        <horizontal_fov>1.212550</horizontal_fov>
        <image>
          <format>R8G8B8</format>
          <width>1280</width>
          <height>720</height>
        </image>
        <clip>
          <near>0.1</near>
          <far>10</far>
        </clip>
        <intrinsics>
          <fx>923.003325</fx>
          <fy>923.003325</fy>
          <cx>626</cx>
          <cy>364</cy>
        </intrinsics>
      </camera>
      <plugin filename="libgazebo_ros_openni_kinect.so" name="camera_plugin">
        <alwaysOn>true</alwaysOn>
        <!-- <baseline>0.2</baseline> -->
        <updateRate>0.0</updateRate>
        <cameraName>hand_eye</cameraName>
        <imageTopicName>/hand_eye/color/image_raw</imageTopicName>
        <cameraInfoTopicName>/hand_eye/color/camera_info</cameraInfoTopicName>
        <depthImageTopicName>/hand_eye/depth/image_rect_raw</depthImageTopicName>
        <depthImageCameraInfoTopicName>/hand_eye/depth/camera_info</depthImageCameraInfoTopicName>
        <pointCloudTopicName>/hand_eye/depth/color/points</pointCloudTopicName>
        <frameName>hand_eye_depth_optical_frame</frameName>
        <pointCloudCutoff>0.1</pointCloudCutoff>
        <pointCloudCutoffMax>10</pointCloudCutoffMax>
        <Cx>626</Cx>
        <Cy>364</Cy>
        <focalLength>923.003325</focalLength>
      </plugin>
    </sensor>
  </gazebo>
  <!-- camera body, with origin at bottom screw mount -->
  <joint name="hand_eye_joint" type="fixed">
    <origin rpy="-2.68850999 -1.56973844 -1.20267232" xyz="0.06585917 -0.06861364 0.14820608"/>
    <parent link="panda_link7"/>
    <child link="hand_eye_bottom_screw_frame"/>
  </joint>
  <link name="hand_eye_bottom_screw_frame"/>
  <joint name="hand_eye_link_joint" type="fixed">
    <origin rpy="0 0 0" xyz="0.010600000000000002 0.0175 0.0125"/>
    <parent link="hand_eye_bottom_screw_frame"/>
    <child link="hand_eye_link"/>
  </joint>
  <link name="hand_eye_link">
    <visual>
      <!-- the mesh origin is at front plate in between the two infrared camera axes -->
      <origin rpy="1.5707963267948966 0 1.5707963267948966" xyz="0.0043 -0.0175 0"/>
      <geometry>
        <mesh filename="/realsense2_description/meshes/d435.dae"/>
      </geometry>
    </visual>
    <collision>
      <origin rpy="0 0 0" xyz="0 -0.0175 0"/>
      <geometry>
        <box size="0.02505 0.09 0.025"/>
      </geometry>
    </collision>
    <inertial>
      <!-- The following are not reliable values, and should not be used for modeling -->
      <mass value="0.072"/>
      <origin xyz="0 0 0"/>
      <inertia ixx="0.003881243" ixy="0.0" ixz="0.0" iyy="0.000498940" iyz="0.0" izz="0.003879257"/>
    </inertial>
  </link>
  <!-- camera depth joints and links -->
  <joint name="hand_eye_depth_joint" type="fixed">
    <origin rpy="0 0 0" xyz="0 0 0"/>
    <parent link="hand_eye_link"/>
    <child link="hand_eye_depth_frame"/>
  </joint>
  <link name="hand_eye_depth_frame"/>
  <joint name="hand_eye_depth_optical_joint" type="fixed">
    <origin rpy="-1.5707963267948966 0 -1.5707963267948966" xyz="0 0 0"/>
    <parent link="hand_eye_depth_frame"/>
    <child link="hand_eye_depth_optical_frame"/>
  </joint>
  <link name="hand_eye_depth_optical_frame"/>
  <!-- camera left IR joints and links -->
  <joint name="hand_eye_infra1_joint" type="fixed">
    <origin rpy="0 0 0" xyz="0 0.0 0"/>
    <parent link="hand_eye_link"/>
    <child link="hand_eye_infra1_frame"/>
  </joint>
  <link name="hand_eye_infra1_frame"/>
  <joint name="hand_eye_infra1_optical_joint" type="fixed">
    <origin rpy="-1.5707963267948966 0 -1.5707963267948966" xyz="0 0 0"/>
    <parent link="hand_eye_infra1_frame"/>
    <child link="hand_eye_infra1_optical_frame"/>
  </joint>
  <link name="hand_eye_infra1_optical_frame"/>
  <!-- camera right IR joints and links -->
  <joint name="hand_eye_infra2_joint" type="fixed">
    <origin rpy="0 0 0" xyz="0 -0.05 0"/>
    <parent link="hand_eye_link"/>
    <child link="hand_eye_infra2_frame"/>
  </joint>
  <link name="hand_eye_infra2_frame"/>
  <joint name="hand_eye_infra2_optical_joint" type="fixed">
    <origin rpy="-1.5707963267948966 0 -1.5707963267948966" xyz="0 0 0"/>
    <parent link="hand_eye_infra2_frame"/>
    <child link="hand_eye_infra2_optical_frame"/>
  </joint>
  <link name="hand_eye_infra2_optical_frame"/>
  <!-- camera color joints and links -->
  <joint name="hand_eye_color_joint" type="fixed">
    <origin rpy="0 0 0" xyz="0 0.015 0"/>
    <parent link="hand_eye_link"/>
    <child link="hand_eye_color_frame"/>
  </joint>
  <link name="hand_eye_color_frame"/>
  <joint name="hand_eye_color_optical_joint" type="fixed">
    <origin rpy="-1.5707963267948966 0 -1.5707963267948966" xyz="0 0 0"/>
    <parent link="hand_eye_color_frame"/>
    <child link="hand_eye_color_optical_frame"/>
  </joint>
  <link name="hand_eye_color_optical_frame"/>
  <!-- Rigid fix between SMB and Panda -->
  <link name="arm_mount_link"/>
  <joint name="arm_mount_joint" type="fixed">
    <parent link="base_link"/>
    <child link="arm_mount_link"/>
    <origin rpy="0 0 0" xyz="0.115 0.0 0.3265"/>
  </joint>
  <gazebo>
    <plugin filename="libgazebo_ros_control.so" name="gazebo_ros_control">
      <robotNamespace>/smb</robotNamespace>
      <robotDescription>smb_description</robotDescription>
      <broadcastTF>False</broadcastTF>
      <robotParam>smb_description</robotParam>
      <robotSimType>gazebo_ros_control/DefaultRobotHWSim</robotSimType>
      <!-- <controlPeriod>${controlPeriod}</controlPeriod> -->
      <!-- <legacyModeNS>true</legacyModeNS> -->
      <!-- TODO(oharley) -->
    </plugin>
  </gazebo>
  <gazebo reference="panda_link0"/>
  <gazebo reference="panda_link1"/>
  <gazebo reference="panda_link2"/>
  <gazebo reference="panda_link3"/>
  <gazebo reference="panda_link4"/>
  <gazebo reference="panda_link5"/>
  <gazebo reference="panda_link6"/>
  <gazebo reference="panda_link7"/>
  <gazebo reference="panda_link8"/>
  <transmission name="panda_joint1_trans">
    <type>transmission_interface/SimpleTransmission</type>
    <joint name="panda_joint1">
      <hardwareInterface>hardware_interface/PositionJointInterface</hardwareInterface>
    </joint>
    <actuator name="panda_joint1_motor">
      <mechanicalReduction>1</mechanicalReduction>
    </actuator>
  </transmission>
  <transmission name="panda_joint2_trans">
    <type>transmission_interface/SimpleTransmission</type>
    <joint name="panda_joint2">
      <hardwareInterface>hardware_interface/PositionJointInterface</hardwareInterface>
    </joint>
    <actuator name="panda_joint2_motor">
      <mechanicalReduction>1</mechanicalReduction>
    </actuator>
  </transmission>
  <transmission name="panda_joint3_trans">
    <type>transmission_interface/SimpleTransmission</type>
    <joint name="panda_joint3">
      <hardwareInterface>hardware_interface/PositionJointInterface</hardwareInterface>
    </joint>
    <actuator name="panda_joint3_motor">
      <mechanicalReduction>1</mechanicalReduction>
    </actuator>
  </transmission>
  <transmission name="panda_joint4_trans">
    <type>transmission_interface/SimpleTransmission</type>
    <joint name="panda_joint4">
      <hardwareInterface>hardware_interface/PositionJointInterface</hardwareInterface>
    </joint>
    <actuator name="panda_joint4_motor">
      <mechanicalReduction>1</mechanicalReduction>
    </actuator>
  </transmission>
  <transmission name="panda_joint5_trans">
    <type>transmission_interface/SimpleTransmission</type>
    <joint name="panda_joint5">
      <hardwareInterface>hardware_interface/PositionJointInterface</hardwareInterface>
    </joint>
    <actuator name="panda_joint5_motor">
      <mechanicalReduction>1</mechanicalReduction>
    </actuator>
  </transmission>
  <transmission name="panda_joint6_trans">
    <type>transmission_interface/SimpleTransmission</type>
    <joint name="panda_joint6">
      <hardwareInterface>hardware_interface/PositionJointInterface</hardwareInterface>
    </joint>
    <actuator name="panda_joint6_motor">
      <mechanicalReduction>1</mechanicalReduction>
    </actuator>
  </transmission>
  <transmission name="panda_joint7_trans">
    <type>transmission_interface/SimpleTransmission</type>
    <joint name="panda_joint7">
      <hardwareInterface>hardware_interface/PositionJointInterface</hardwareInterface>
    </joint>
    <actuator name="panda_joint7_motor">
      <mechanicalReduction>1</mechanicalReduction>
    </actuator>
  </transmission>
  <gazebo>
    <plugin filename="libgazebo_ros_control.so" name="gazebo_ros_control">
      <robotNamespace>/panda</robotNamespace>
      <robotDescription>arm_description</robotDescription>
      <robotParam>arm_description</robotParam>
      <robotSimType>gazebo_ros_control/DefaultRobotHWSim</robotSimType>
    </plugin>
  </gazebo>
</robot>
