<?xml version="1.0" ?>
<!-- =================================================================================== -->
<!-- |    This document was autogenerated by xacro from /home/marko/MT/catkin_ws/src/moma/moma_demos/articulated_demo/data/models/container/container_removable_lid.urdf.xacro | -->
<!-- |    EDITING THIS FILE BY HAND IS NOT RECOMMENDED                                 | -->
<!-- =================================================================================== -->
<robot name="container_no_lid">
  <material name="white">
    <color rgba="1 1 1 1"/>
  </material>
  <material name="dark_brown">
    <color rgba="0.4 0.2 0.0 1"/>
  </material>
  <material name="light_brown">
    <color rgba="0.6 0.29 0.0 1"/>
  </material>
  <material name="silver">
    <color rgba="0.87 0.87 0.87 0.8"/>
  </material>
  <link name="base_link">
    <inertial>
      <origin rpy="0 0 0" xyz="0 0 0"/>
      <mass value="0.0"/>
      <inertia ixx="1" ixy="0" ixz="0" iyy="1" iyz="0" izz="1"/>
    </inertial>
  </link>
  <link name="frame_bottom_plane">
    <contact>
      <lateral_friction value="1.0"/>
    </contact>
    <inertial>
      <origin rpy="0 0 0" xyz="0 0 0"/>
      <mass value="0.2"/>
      <inertia ixx="1" ixy="0" ixz="0" iyy="1" iyz="0" izz="1"/>
    </inertial>
    <visual>
      <origin rpy="0 0 0" xyz="0 0 0"/>
      <geometry>
        <box size="0.3 0.2 0.01"/>
      </geometry>
      <material name="dark_brown"/>
    </visual>
    <collision>
      <origin rpy="0 0 0" xyz="0 0 0"/>
      <geometry>
        <box size="0.3 0.2 0.01"/>
      </geometry>
    </collision>
  </link>
  <link name="frame_back_plane">
    <contact>
      <lateral_friction value="1.0"/>
    </contact>
    <inertial>
      <origin rpy="0 0 0" xyz="0 0 0"/>
      <mass value="0.2"/>
      <inertia ixx="1" ixy="0" ixz="0" iyy="1" iyz="0" izz="1"/>
    </inertial>
    <visual>
      <origin rpy="0 0 0" xyz="0 0 0"/>
      <geometry>
        <box size="0.3 0.09000000000000001 0.01"/>
      </geometry>
      <material name="dark_brown"/>
    </visual>
    <collision>
      <origin rpy="0 0 0" xyz="0 0 0"/>
      <geometry>
        <box size="0.3 0.09000000000000001 0.01"/>
      </geometry>
    </collision>
  </link>
  <joint name="frame_back_joint" type="fixed">
    <origin rpy="1.5707963267948966 0 0" xyz="0 0.095 0.04000000000000001"/>
    <parent link="frame_bottom_plane"/>
    <child link="frame_back_plane"/>
  </joint>
  <link name="frame_left_plane">
    <contact>
      <lateral_friction value="1.0"/>
    </contact>
    <inertial>
      <origin rpy="0 0 0" xyz="0 0 0"/>
      <mass value="0.2"/>
      <inertia ixx="1" ixy="0" ixz="0" iyy="1" iyz="0" izz="1"/>
    </inertial>
    <visual>
      <origin rpy="0 0 0" xyz="0 0 0"/>
      <geometry>
        <box size="0.18000000000000002 0.09000000000000001 0.01"/>
      </geometry>
      <material name="dark_brown"/>
    </visual>
    <collision>
      <origin rpy="0 0 0" xyz="0 0 0"/>
      <geometry>
        <box size="0.18000000000000002 0.09000000000000001 0.01"/>
      </geometry>
    </collision>
  </link>
  <joint name="frame_left_joint" type="fixed">
    <origin rpy="1.5707963267948966 0 1.5707963267948966" xyz="-0.145 0 0.04000000000000001"/>
    <parent link="frame_bottom_plane"/>
    <child link="frame_left_plane"/>
  </joint>
  <link name="frame_right_plane">
    <contact>
      <lateral_friction value="1.0"/>
    </contact>
    <inertial>
      <origin rpy="0 0 0" xyz="0 0 0"/>
      <mass value="0.2"/>
      <inertia ixx="1" ixy="0" ixz="0" iyy="1" iyz="0" izz="1"/>
    </inertial>
    <visual>
      <origin rpy="0 0 0" xyz="0 0 0"/>
      <geometry>
        <box size="0.18000000000000002 0.09000000000000001 0.01"/>
      </geometry>
      <material name="dark_brown"/>
    </visual>
    <collision>
      <origin rpy="0 0 0" xyz="0 0 0"/>
      <geometry>
        <box size="0.18000000000000002 0.09000000000000001 0.01"/>
      </geometry>
    </collision>
  </link>
  <joint name="frame_right_joint" type="fixed">
    <origin rpy="1.5707963267948966 0 1.5707963267948966" xyz="0.145 0 0.04000000000000001"/>
    <parent link="frame_bottom_plane"/>
    <child link="frame_right_plane"/>
  </joint>
  <link name="frame_front_plane">
    <contact>
      <lateral_friction value="1.0"/>
    </contact>
    <inertial>
      <origin rpy="0 0 0" xyz="0 0 0"/>
      <mass value="0.2"/>
      <inertia ixx="1" ixy="0" ixz="0" iyy="1" iyz="0" izz="1"/>
    </inertial>
    <visual>
      <origin rpy="0 0 0" xyz="0 0 0"/>
      <geometry>
        <box size="0.3 0.09000000000000001 0.01"/>
      </geometry>
      <material name="dark_brown"/>
    </visual>
    <collision>
      <origin rpy="0 0 0" xyz="0 0 0"/>
      <geometry>
        <box size="0.3 0.09000000000000001 0.01"/>
      </geometry>
    </collision>
  </link>
  <joint name="frame_front_joint" type="fixed">
    <origin rpy="1.5707963267948966 0 0" xyz="0 -0.095 0.04000000000000001"/>
    <parent link="frame_bottom_plane"/>
    <child link="frame_front_plane"/>
  </joint>
  <joint name="frame_joint" type="fixed">
    <origin rpy="0 0 0" xyz="0 0 0.005"/>
    <parent link="base_link"/>
    <child link="frame_bottom_plane"/>
  </joint>
  <link name="lid_plane">
    <contact>
      <lateral_friction value="1.0"/>
    </contact>
    <inertial>
      <origin rpy="0 0 0" xyz="0 0 0"/>
      <mass value="0.2"/>
      <inertia ixx="1" ixy="0" ixz="0" iyy="1" iyz="0" izz="1"/>
    </inertial>
    <visual>
      <origin rpy="0 0 0" xyz="0 0 0"/>
      <geometry>
        <box size="0.315 0.21000000000000002 0.01"/>
      </geometry>
      <material name="white"/>
    </visual>
    <collision>
      <origin rpy="0 0 0" xyz="0 0 0"/>
      <geometry>
        <box size="0.315 0.21000000000000002 0.01"/>
      </geometry>
    </collision>
  </link>
  <joint name="lid_joint" type="prismatic">
    <origin rpy="0 0 0" xyz="0 0 0.09000000000000001"/>
    <parent link="frame_bottom_plane"/>
    <child link="lid_plane"/>
    <axis xyz="0 0 1"/>
    <dynamics damping="8.0"/>
    <limit effort="10.0" lower="0.0" upper="0.27" velocity="1.5"/>
  </joint>
  <link name="handle">
    <inertial>
      <origin rpy="0 0 0" xyz="0 0 0"/>
      <mass value="0.2"/>
      <inertia ixx="1" ixy="0" ixz="0" iyy="1" iyz="0" izz="1"/>
    </inertial>
    <collision>
      <origin rpy="0 0 0" xyz="0 0 0"/>
      <geometry>
        <cylinder length="0.16000000000000003" radius="0.01"/>
      </geometry>
    </collision>
    <visual>
      <origin rpy="0 0 0" xyz="0 0 0"/>
      <geometry>
        <cylinder length="0.16000000000000003" radius="0.01"/>
      </geometry>
      <material name="silver"/>
    </visual>
  </link>
  <joint name="handle_joint" type="fixed">
    <origin rpy="1.5707963267948966 0 0" xyz="0 0 0.025"/>
    <parent link="lid_plane"/>
    <child link="handle"/>
  </joint>
</robot>

